Workbook

Sheet Your Details
D3: Stones | E3: Pounds
C5: Current Weight | D5: 19 | E5: 0

Sheet Target-lb
B1: 2026 | C1: Jan | D1: Feb | E1: Mar | F1: April | G1: May | H1: June | I1: July | J1: August | K1: September | L1: October | M1: November | N1: December | O1: Loss (lb) | P1: Number Months | Q1: Per Month | R1: Per week | S1: Per Week
A2: Pounds (lbs) | B2: ='Your Details'!D5*14+'Your Details'!E5 -> 266 | C2: =B2-7 -> 259 | D2: =C2-7 -> 252 | E2: =D2-7 -> 245 | F2: =E2-7 -> 238 | G2: =F2-7 -> 231 | H2: =G2-7 -> 224 | I2: =H2-7 -> 217 | J2: =I2-7 -> 210 | ... N2: =M2-7 -> 182 | O2: =B2-N2 -> 84 | P2: 12 | Q2: =O2/P2 -> 7 | R2: =Q2/4 -> 1.75 | S2: =7/4 -> 1.75
A4: 46027 | B4: =ISOWEEKNUM(A4)-1 -> 1 | C4: =(B2-$S$2) -> 264.25
A5: =A4+7 -> 46034 | B5: =ISOWEEKNUM(A5)-1 -> 2 | C5: =C4-$S$2 -> 262.5
A6: =A5+7 -> 46041 | B6: =ISOWEEKNUM(A6)-1 -> 3 | C6: =C5-$S$2 -> 260.75
A7: =A6+7 -> 46048 | B7: =ISOWEEKNUM(A7)-1 -> 4 | C7: =C6-$S$2 -> 259
A9: =A7+7 -> 46055 | B9: =ISOWEEKNUM(A9)-1 -> 5 | D9: =C7-$S$2 -> 257.25
A10: =A9+7 -> 46062 | B10: =ISOWEEKNUM(A10)-1 -> 6 | D10: =D9-$S$2 -> 255.5
A11: =A10+7 -> 46069 | B11: =ISOWEEKNUM(A11)-1 -> 7 | D11: =D10-$S$2 -> 253.75
A12: =A11+7 -> 46076 | B12: =ISOWEEKNUM(A12)-1 -> 8 | D12: =D11-$S$2 -> 252
A14: =A12+7 -> 46083 | B14: =ISOWEEKNUM(A14)-1 -> 9 | E14: =D12-$S$2 -> 250.25
A15: =A14+7 -> 46090 | B15: =ISOWEEKNUM(A15)-1 -> 10 | E15: =E14-$S$2 -> 248.5
A16: =A15+7 -> 46097 | B16: =ISOWEEKNUM(A16)-1 -> 11 | E16: =E15-$S$2 -> 246.75
A17: =A16+7 -> 46104 | B17: =ISOWEEKNUM(A17)-1 -> 12 | E17: =E16-$S$2 -> 245
A19: =A17+7 -> 46111 | B19: =ISOWEEKNUM(A19)-1 -> 13 | F19: =E17--$S$2 -> 246.75
A20: =A19+7 -> 46118 | B20: =ISOWEEKNUM(A20)-1 -> 14 | F20: =F19-$S$2 -> 245
A21: =A20+7 -> 46125 | B21: =ISOWEEKNUM(A21)-1 -> 15 | F21: =F20-$S$2 -> 243.25
A22: =A21+7 -> 46132 | B22: =ISOWEEKNUM(A22)-1 -> 16 | F22: =F21-$S$2 -> 241.5
A23: =A22+7 -> 46139 | B23: =ISOWEEKNUM(A23)-1 -> 17 | F23: =F22-$S$2 -> 239.75
A25: =A23+7 -> 46146 | B25: =ISOWEEKNUM(A25)-1 -> 18 | G25: =F23-$S$2 -> 238
A26: =A25+7 -> 46153 | B26: =ISOWEEKNUM(A26)-1 -> 19 | G26: =G25-$S$2 -> 236.25
A27: =A26+7 -> 46160 | B27: =ISOWEEKNUM(A27)-1 -> 20 | G27: =G26-$S$2 -> 234.5
A28: =A27+7 -> 46167 | B28: =ISOWEEKNUM(A28)-1 -> 21 | G28: =G27-$S$2 -> 232.75
A30: =A28+7 -> 46174 | B30: =ISOWEEKNUM(A30)-1 -> 22 | H30: =G28-$S$2 -> 231
A31: =A30+7 -> 46181 | B31: =ISOWEEKNUM(A31)-1 -> 23 | H31: =H30-$S$2 -> 229.25
A32: =A31+7 -> 46188 | B32: =ISOWEEKNUM(A32)-1 -> 24 | H32: =H31-$S$2 -> 227.5
A33: =A32+7 -> 46195 | B33: =ISOWEEKNUM(A33)-1 -> 25 | H33: =H32-$S$2 -> 225.75
A34: =A33+7 -> 46202 | B34: =ISOWEEKNUM(A34)-1 -> 26 | H34: =H33-$S$2 -> 224
A36: =A34+7 -> 46209 | B36: =ISOWEEKNUM(A36)-1 -> 27 | I36: =H34-$S$2 -> 222.25
A37: =A36+7 -> 46216 | B37: =ISOWEEKNUM(A37)-1 -> 28 | I37: =I36-$S$2 -> 220.5
A38: =A37+7 -> 46223 | B38: =ISOWEEKNUM(A38)-1 -> 29 | I38: =I37-$S$2 -> 218.75
A39: =A38+7 -> 46230 | B39: =ISOWEEKNUM(A39)-1 -> 30 | I39: =I38-$S$2 -> 217
A41: =A39+7 -> 46237 | B41: =ISOWEEKNUM(A41)-1 -> 31 | J41: =I39-$S$2 -> 215.25
A42: =A41+7 -> 46244 | B42: =ISOWEEKNUM(A42)-1 -> 32 | J42: =J41-$S$2 -> 213.5
A43: =A42+7 -> 46251 | B43: =ISOWEEKNUM(A43)-1 -> 33 | J43: =J42-$S$2 -> 211.75
A44: =A43+7 -> 46258 | B44: =ISOWEEKNUM(A44)-1 -> 34 | J44: =J43-$S$2 -> 210
A46: =A44+7 -> 46265 | B46: =ISOWEEKNUM(A46)-1 -> 35 | K46: =J44-$S$2 -> 208.25
A47: =A46+7 -> 46272 | B47: =ISOWEEKNUM(A47)-1 -> 36 | K47: =K46-$S$2 -> 206.5
A48: =A47+7 -> 46279 | B48: =ISOWEEKNUM(A48)-1 -> 37 | K48: =K47-$S$2 -> 204.75
A49: =A48+7 -> 46286 | B49: =ISOWEEKNUM(A49)-1 -> 38 | K49: =K48-$S$2 -> 203
...

Sheet Target-st
B1: 2026 | C1: Jan | D1: Feb | E1: Mar | F1: April | G1: May | H1: June | I1: July | J1: August | K1: September | L1: October | M1: November | N1: December | O1: Loss (st) | P1: Number Months | Q1: Per Month (st) | R1: Per week (st) | S1: Per Week (st)
A2: Stones | B2: =('Your Details'!D5*14+'Your Details'!E5)/14 -> 19 | C2: =B2-0.5 -> 18.5 | D2: =C2-0.5 -> 18 | E2: =D2-0.5 -> 17.5 | F2: =E2-0.5 -> 17 | G2: =F2-0.5 -> 16.5 | H2: =G2-0.5 -> 16 | I2: =H2-0.5 -> 15.5 | J2: =I2-0.5 -> 15 | ... N2: =M2-0.5 -> 13 | O2: =B2-N2 -> 6 | P2: 12 | Q2: =O2/P2 -> 0.5 | R2: =Q2/4 -> 0.125 | S2: =(7/4)/14 -> 0.125
A4: 46027 | B4: =ISOWEEKNUM(A4)-1 -> 1 | C4: =(B2-$S$2) -> 18.875
A5: =A4+7 -> 46034 | B5: =ISOWEEKNUM(A5)-1 -> 2 | C5: =C4-$S$2 -> 18.75
A6: =A5+7 -> 46041 | B6: =ISOWEEKNUM(A6)-1 -> 3 | C6: =C5-$S$2 -> 18.625
A7: =A6+7 -> 46048 | B7: =ISOWEEKNUM(A7)-1 -> 4 | C7: =C6-$S$2 -> 18.5
A9: =A7+7 -> 46055 | B9: =ISOWEEKNUM(A9)-1 -> 5 | D9: =C7-$S$2 -> 18.375
A10: =A9+7 -> 46062 | B10: =ISOWEEKNUM(A10)-1 -> 6 | D10: =D9-$S$2 -> 18.25
A11: =A10+7 -> 46069 | B11: =ISOWEEKNUM(A11)-1 -> 7 | D11: =D10-$S$2 -> 18.125
A12: =A11+7 -> 46076 | B12: =ISOWEEKNUM(A12)-1 -> 8 | D12: =D11-$S$2 -> 18
A14: =A12+7 -> 46083 | B14: =ISOWEEKNUM(A14)-1 -> 9 | E14: =D12-$S$2 -> 17.875
A15: =A14+7 -> 46090 | B15: =ISOWEEKNUM(A15)-1 -> 10 | E15: =E14-$S$2 -> 17.75
A16: =A15+7 -> 46097 | B16: =ISOWEEKNUM(A16)-1 -> 11 | E16: =E15-$S$2 -> 17.625
A17: =A16+7 -> 46104 | B17: =ISOWEEKNUM(A17)-1 -> 12 | E17: =E16-$S$2 -> 17.5
A19: =A17+7 -> 46111 | B19: =ISOWEEKNUM(A19)-1 -> 13 | F19: =E17--$S$2 -> 17.625
A20: =A19+7 -> 46118 | B20: =ISOWEEKNUM(A20)-1 -> 14 | F20: =F19-$S$2 -> 17.5
A21: =A20+7 -> 46125 | B21: =ISOWEEKNUM(A21)-1 -> 15 | F21: =F20-$S$2 -> 17.375
A22: =A21+7 -> 46132 | B22: =ISOWEEKNUM(A22)-1 -> 16 | F22: =F21-$S$2 -> 17.25
A23: =A22+7 -> 46139 | B23: =ISOWEEKNUM(A23)-1 -> 17 | F23: =F22-$S$2 -> 17.125
A25: =A23+7 -> 46146 | B25: =ISOWEEKNUM(A25)-1 -> 18 | G25: =F23-$S$2 -> 17
A26: =A25+7 -> 46153 | B26: =ISOWEEKNUM(A26)-1 -> 19 | G26: =G25-$S$2 -> 16.875
A27: =A26+7 -> 46160 | B27: =ISOWEEKNUM(A27)-1 -> 20 | G27: =G26-$S$2 -> 16.75
A28: =A27+7 -> 46167 | B28: =ISOWEEKNUM(A28)-1 -> 21 | G28: =G27-$S$2 -> 16.625
A30: =A28+7 -> 46174 | B30: =ISOWEEKNUM(A30)-1 -> 22 | H30: =G28-$S$2 -> 16.5
A31: =A30+7 -> 46181 | B31: =ISOWEEKNUM(A31)-1 -> 23 | H31: =H30-$S$2 -> 16.375
A32: =A31+7 -> 46188 | B32: =ISOWEEKNUM(A32)-1 -> 24 | H32: =H31-$S$2 -> 16.25
A33: =A32+7 -> 46195 | B33: =ISOWEEKNUM(A33)-1 -> 25 | H33: =H32-$S$2 -> 16.125
A34: =A33+7 -> 46202 | B34: =ISOWEEKNUM(A34)-1 -> 26 | H34: =H33-$S$2 -> 16
A36: =A34+7 -> 46209 | B36: =ISOWEEKNUM(A36)-1 -> 27 | I36: =H34-$S$2 -> 15.875
A37: =A36+7 -> 46216 | B37: =ISOWEEKNUM(A37)-1 -> 28 | I37: =I36-$S$2 -> 15.75
A38: =A37+7 -> 46223 | B38: =ISOWEEKNUM(A38)-1 -> 29 | I38: =I37-$S$2 -> 15.625
A39: =A38+7 -> 46230 | B39: =ISOWEEKNUM(A39)-1 -> 30 | I39: =I38-$S$2 -> 15.5
A41: =A39+7 -> 46237 | B41: =ISOWEEKNUM(A41)-1 -> 31 | J41: =I39-$S$2 -> 15.375
A42: =A41+7 -> 46244 | B42: =ISOWEEKNUM(A42)-1 -> 32 | J42: =J41-$S$2 -> 15.25
A43: =A42+7 -> 46251 | B43: =ISOWEEKNUM(A43)-1 -> 33 | J43: =J42-$S$2 -> 15.125
A44: =A43+7 -> 46258 | B44: =ISOWEEKNUM(A44)-1 -> 34 | J44: =J43-$S$2 -> 15
A45: =A44+7 -> 46265 | B45: =ISOWEEKNUM(A45)-1 -> 35 | J45: =J44-$S$2 -> 14.875
A47: =A45+7 -> 46272 | B47: =ISOWEEKNUM(A47)-1 -> 36 | K47: =J45-$S$2 -> 14.75
A48: =A47+7 -> 46279 | B48: =ISOWEEKNUM(A48)-1 -> 37 | K48: =K47-$S$2 -> 14.625
A49: =A48+7 -> 46286 | B49: =ISOWEEKNUM(A49)-1 -> 38 | K49: =K48-$S$2 -> 14.5
...

Sheet Actuals
A1: Actuals
A3: Month | B3: Week # | C3: Start Date | E3: Monday | F3: Tuesday | G3: Wednesday | H3: Thursday | I3: Friday | J3: Saturday | K3: Sunday | L3: Min | M3: Max
A5: =text(C5,"MMMM") -> January | B5: =ISOWEEKNUM(C5)-1 -> 1 | C5: 46027 | E5: =January!D4 -> 19 | F5: =January!E4 -> 19 | G5: =January!F4 -> 19 | H5: =January!G4 -> 19 | I5: =January!H4 -> 19 | J5: =January!I4 -> 19 | K5: =January!J4 -> 19 | L5: =min(E5:K5) -> 19 | M5: =MAX(E5:K5) -> 19
B6: =ISOWEEKNUM(C6)-1 -> 2 | C6: =C5+7 -> 46034 | E6: =January!D8 -> 19 | F6: =January!E8 -> 19 | G6: =January!F8 -> 19 | H6: =January!G8 -> 19 | I6: =January!H8 -> 19 | J6: =January!I8 -> 19 | K6: =January!J8 -> 19 | L6: =January!K8 -> 19 | M6: =January!L8 -> 19
B7: =ISOWEEKNUM(C7)-1 -> 3 | C7: =C6+7 -> 46041 | E7: =January!D12 -> 19 | F7: =January!E12 -> 19 | G7: =January!F12 -> 19 | H7: =January!G12 -> 19 | I7: =January!H12 -> 19 | J7: =January!I12 -> 19 | K7: =January!J12 -> 19 | L7: =January!K12 -> 19 | M7: =January!L12 -> 19
B8: =ISOWEEKNUM(C8)-1 -> 4 | C8: =C7+7 -> 46048 | E8: =January!D16 -> 19 | F8: =January!E16 -> 19 | G8: =January!F16 -> 19 | H8: =January!G16 -> 19 | I8: =January!H16 -> 19 | J8: =January!I16 -> 19 | K8: =January!J16 -> 19 | L8: =January!K16 -> 19 | M8: =January!L16 -> 19
A10: =text(C10,"MMMM") -> February | B10: =ISOWEEKNUM(C10)-1 -> 5 | C10: =C8+7 -> 46055 | E10: =February!D4 -> 19 | F10: =February!E4 -> 19 | G10: =February!F4 -> 19 | H10: =February!G4 -> 19 | I10: =February!H4 -> 19 | J10: =February!I4 -> 19 | K10: =February!J4 -> 19 | L10: =min(E10:K10) -> 19 | M10: =MAX(E10:K10) -> 19
B11: =ISOWEEKNUM(C11)-1 -> 6 | C11: =C10+7 -> 46062 | E11: =February!D12 -> 19 | F11: =February!E12 -> 19 | G11: =February!F12 -> 19 | H11: =February!G12 -> 19 | I11: =February!H12 -> 19 | J11: =February!I12 -> 19 | K11: =February!J12 -> 19 | L11: =min(E11:K11) -> 19 | M11: =MAX(E11:K11) -> 19
B12: =ISOWEEKNUM(C12)-1 -> 7 | C12: =C11+7 -> 46069 | E12: =February!D12 -> 19 | F12: =February!E12 -> 19 | G12: =February!F12 -> 19 | H12: =February!G12 -> 19 | I12: =February!H12 -> 19 | J12: =February!I12 -> 19 | K12: =February!J12 -> 19 | L12: =min(E12:K12) -> 19 | M12: =MAX(E12:K12) -> 19
B13: =ISOWEEKNUM(C13)-1 -> 8 | C13: =C12+7 -> 46076 | E13: =February!D16 -> 19 | F13: =February!E16 -> 19 | G13: =February!F16 -> 19 | H13: =February!G16 -> 19 | I13: =February!H16 -> 19 | J13: =February!I16 -> 19 | K13: =February!J16 -> 19 | L13: =min(E13:K13) -> 19 | M13: =MAX(E13:K13) -> 19
A15: =text(C15,"MMMM") -> March | B15: =ISOWEEKNUM(C15)-1 -> 9 | C15: =C13+7 -> 46083 | E15: =March!D4 -> 19 | F15: =March!E4 -> 19 | G15: =March!F4 -> 19 | H15: =March!G4 -> 19 | I15: =March!H4 -> 19 | J15: =March!I4 -> 19 | K15: =March!J4 -> 19 | L15: =min(E15:K15) -> 19 | M15: =MAX(E15:K15) -> 19
B16: =ISOWEEKNUM(C16)-1 -> 10 | C16: =C15+7 -> 46090 | E16: =March!D8 -> 19 | F16: =March!E8 -> 19 | G16: =March!F8 -> 19 | H16: =March!G8 -> 19 | I16: =March!H8 -> 19 | J16: =March!I8 -> 19 | K16: =March!J8 -> 19 | L16: =min(E16:K16) -> 19 | M16: =MAX(E16:K16) -> 19
B17: =ISOWEEKNUM(C17)-1 -> 11 | C17: =C16+7 -> 46097 | E17: =March!D12 -> 19 | F17: =March!E12 -> 19 | G17: =March!F12 -> 19 | H17: =March!G12 -> 19 | I17: =March!H12 -> 19 | J17: =March!I12 -> 19 | K17: =March!J12 -> 19 | L17: =min(E17:K17) -> 19 | M17: =MAX(E17:K17) -> 19
B18: =ISOWEEKNUM(C18)-1 -> 12 | C18: =C17+7 -> 46104 | E18: =March!E16 -> 19 | F18: =March!F16 -> 19 | G18: =March!G16 -> 19 | H18: =March!H16 -> 19 | I18: =March!I16 -> 19 | J18: =March!J16 -> 19 | K18: =March!K16 -> 19 | L18: =min(E18:K18) -> 19 | M18: =MAX(E18:K18) -> 19
A20: =text(C20+7,"MMMM") -> April | B20: =ISOWEEKNUM(C20)-1 -> 13 | C20: =C18+7 -> 46111 | E20: =April!D4 -> 19 | F20: =April!E4 -> 19 | G20: =April!F4 -> 19 | H20: =April!G4 -> 19 | I20: =April!H4 -> 19 | J20: =April!I4 -> 19 | K20: =April!J4 -> 19 | L20: =min(E20:K20) -> 19 | M20: =MAX(E20:K20) -> 19
B21: =ISOWEEKNUM(C21)-1 -> 14 | C21: =C20+7 -> 46118 | E21: =April!D8 -> 19 | F21: =April!E8 -> 19 | G21: =April!F8 -> 19 | H21: =April!G8 -> 19 | I21: =April!H8 -> 19 | J21: =April!I8 -> 19 | K21: =April!J8 -> 19 | L21: =min(E21:K21) -> 19 | M21: =MAX(E21:K21) -> 19
B22: =ISOWEEKNUM(C22)-1 -> 15 | C22: =C21+7 -> 46125 | E22: =April!D12 -> 19 | F22: =April!E12 -> 19 | G22: =April!F12 -> 19 | H22: =April!G12 -> 19 | I22: =April!H12 -> 19 | J22: =April!I12 -> 19 | K22: =April!J12 -> 19 | L22: =min(E22:K22) -> 19 | M22: =MAX(E22:K22) -> 19
B23: =ISOWEEKNUM(C23)-1 -> 16 | C23: =C22+7 -> 46132 | E23: =April!D16 -> 19 | F23: =April!E16 -> 19 | G23: =April!F16 -> 19 | H23: =April!G16 -> 19 | I23: =April!H16 -> 19 | J23: =April!I16 -> 19 | K23: =April!J16 -> 19 | L23: =min(E23:K23) -> 19 | M23: =MAX(E23:K23) -> 19
B24: =ISOWEEKNUM(C24)-1 -> 17 | C24: =C23+7 -> 46139 | E24: =April!D20 -> 19 | F24: =April!E20 -> 19 | G24: =April!F20 -> 19 | H24: =April!G20 -> 19 | I24: =April!H20 -> 19 | J24: =April!I20 -> 19 | K24: =April!J20 -> 19 | L24: =min(E24:K24) -> 19 | M24: =MAX(E24:K24) -> 19
A26: =text(C26,"MMMM") -> May | B26: =ISOWEEKNUM(C26)-1 -> 18 | C26: =C24+7 -> 46146 | E26: =May!D4 -> 19 | F26: =May!E4 -> 19 | G26: =May!F4 -> 19 | H26: =May!G4 -> 19 | I26: =May!H4 -> 19 | J26: =May!I4 -> 19 | K26: =May!J4 -> 19 | L26: =May!K4 -> 19 | M26: =MAX(E26:K26) -> 19
B27: =ISOWEEKNUM(C27)-1 -> 19 | C27: =C26+7 -> 46153 | E27: =May!D8 -> 19 | F27: =May!E8 -> 19 | G27: =May!F8 -> 19 | H27: =May!G8 -> 19 | I27: =May!H8 -> 19 | J27: =May!I8 -> 19 | K27: =May!J8 -> 19 | L27: =min(E27:K27) -> 19 | M27: =MAX(E27:K27) -> 19
B28: =ISOWEEKNUM(C28)-1 -> 20 | C28: =C27+7 -> 46160 | E28: =May!D12 -> 19 | F28: =May!E12 -> 19 | G28: =May!F12 -> 19 | H28: =May!G12 -> 19 | I28: =May!H12 -> 19 | J28: =May!I12 -> 19 | K28: =May!J12 -> 19 | L28: =min(E28:K28) -> 19 | M28: =MAX(E28:K28) -> 19
B29: =ISOWEEKNUM(C29)-1 -> 21 | C29: =C28+7 -> 46167 | E29: =May!D16 -> 19 | F29: =May!E16 -> 19 | G29: =May!F16 -> 19 | H29: =May!G16 -> 19 | I29: =May!H16 -> 19 | J29: =May!I16 -> 19 | K29: =May!J16 -> 19 | L29: =min(E29:K29) -> 19 | M29: =MAX(E29:K29) -> 19
A31: =text(C31,"MMMM") -> June | B31: =ISOWEEKNUM(C31)-1 -> 22 | C31: =C29+7 -> 46174 | E31: =June!D4 -> 16.5 | F31: =June!E4 -> 16.5 | G31: =June!F4 -> 16.5 | H31: =June!G4 -> 16.5 | I31: =June!H4 -> 16.5 | J31: =June!I4 -> 16.5 | K31: =June!J4 -> 16.5 | L31: =min(E31:K31) -> 16.5 | M31: =MAX(E31:K31) -> 16.5
B32: =ISOWEEKNUM(C32)-1 -> 23 | C32: =C31+7 -> 46181 | E32: =June!D8 -> 16.5 | F32: =June!E8 -> 16.5 | G32: =June!F8 -> 16.5 | H32: =June!G8 -> 16.5 | I32: =June!H8 -> 16.5 | J32: =June!I8 -> 16.5 | K32: =June!J8 -> 16.5 | L32: =min(E32:K32) -> 16.5 | M32: =MAX(E32:K32) -> 16.5
B33: =ISOWEEKNUM(C33)-1 -> 24 | C33: =C32+7 -> 46188 | E33: =June!D12 -> 16.5 | F33: =June!E12 -> 16.5 | G33: =June!F12 -> 16.5 | H33: =June!G12 -> 16.5 | I33: =June!H12 -> 16.157143 | J33: =June!I12 -> 16.157143 | K33: =June!J12 -> 16.157143 | L33: =min(E33:K33) -> 16.157143 | M33: =MAX(E33:K33) -> 16.5
B34: =ISOWEEKNUM(C34)-1 -> 25 | C34: =C33+7 -> 46195 | E34: =June!D16 -> 16.157143 | F34: =June!E16 -> 16.157143 | G34: =June!F16 -> 16.157143 | H34: =June!G16 -> 16.157143 | I34: =June!H16 -> 16.157143 | J34: =June!I16 -> 16.157143 | K34: =June!J16 -> 16.157143 | L34: =min(E34:K34) -> 16.157143 | M34: =MAX(E34:K34) -> 16.157143
B35: =ISOWEEKNUM(C35)-1 -> 26 | C35: =C34+7 -> 46202 | E35: =June!D20 -> 16.157143 | F35: =June!E20 -> 16.157143 | G35: =June!F20 -> 16.157143 | H35: =June!G20 -> 16.157143 | I35: =June!H20 -> 16.157143 | J35: =June!I20 -> 16.157143 | K35: =June!J20 -> 16.157143 | L35: =min(E35:K35) -> 16.157143 | M35: =MAX(E35:K35) -> 16.157143
A37: =text(C37,"MMMM") -> July | B37: =ISOWEEKNUM(C37)-1 -> 27 | C37: =C35+7 -> 46209 | E37: =July!D4 -> 16.157143 | F37: =July!E4 -> 16.157143 | G37: =July!F4 -> 16.157143 | H37: =July!G4 -> 16.157143 | I37: =July!H4 -> 16.157143 | J37: =July!I4 -> 16.157143 | K37: =July!J4 -> 16.157143 | L37: =min(E37:K37) -> 16.157143 | M37: =MAX(E37:K37) -> 16.157143
B38: =ISOWEEKNUM(C38)-1 -> 28 | C38: =C37+7 -> 46216 | E38: =July!D8 -> 16.157143 | F38: =July!E8 -> 16.157143 | G38: =July!F8 -> 16.157143 | H38: =July!G8 -> 16.157143 | I38: =July!H8 -> 16.157143 | J38: =July!I8 -> 16.157143 | K38: =July!J8 -> 16.157143 | L38: =min(E38:K38) -> 16.157143 | M38: =MAX(E38:K38) -> 16.157143
B39: =ISOWEEKNUM(C39)-1 -> 29 | C39: =C38+7 -> 46223 | E39: =July!D12 -> 16.157143 | F39: =July!E12 -> 16.157143 | G39: =July!F12 -> 16.157143 | H39: =July!G12 -> 16.157143 | I39: =July!H12 -> 16.157143 | J39: =July!I12 -> 16.157143 | K39: =July!J12 -> 16.157143 | L39: =min(E39:K39) -> 16.157143 | M39: =MAX(E39:K39) -> 16.157143
B40: =ISOWEEKNUM(C40)-1 -> 30 | C40: =C39+7 -> 46230 | E40: =July!D16 -> 16.157143 | F40: =July!E16 -> 16.157143 | G40: =July!F16 -> 16.157143 | H40: =July!G16 -> 16.157143 | I40: =July!H16 -> 16.157143 | J40: =July!I16 -> 16.157143 | K40: =July!J16 -> 16.157143 | L40: =min(E40:K40) -> 16.157143 | M40: =MAX(E40:K40) -> 16.157143
A42: =text(C42,"MMMM") -> August | B42: =ISOWEEKNUM(C42)-1 -> 31 | C42: =C40+7 -> 46237 | E42: =August!D4 -> 16.157143 | F42: =August!E4 -> 16.157143 | G42: =August!F4 -> 16.157143 | H42: =August!G4 -> 16.157143 | I42: =August!H4 -> 16.157143 | J42: =August!I4 -> 16.157143 | K42: =August!J4 -> 16.157143 | L42: =min(E42:K42) -> 16.157143 | M42: =MAX(E42:K42) -> 16.157143
B43: =ISOWEEKNUM(C43)-1 -> 32 | C43: =C42+7 -> 46244 | E43: =August!D8 -> 16.157143 | F43: =August!E8 -> 16.157143 | G43: =August!F8 -> 16.157143 | H43: =August!G8 -> 16.157143 | I43: =August!H8 -> 16.157143 | J43: =August!I8 -> 16.157143 | K43: =August!J8 -> 16.157143 | L43: =min(E43:K43) -> 16.157143 | M43: =MAX(E43:K43) -> 16.157143
B44: =ISOWEEKNUM(C44)-1 -> 33 | C44: =C43+7 -> 46251 | E44: =August!D12 -> 16.157143 | F44: =August!E12 -> 16.157143 | G44: =August!F12 -> 16.157143 | H44: =August!G12 -> 16.157143 | I44: =August!H12 -> 16.157143 | J44: =August!I12 -> 16.157143 | K44: =August!J12 -> 16.157143 | L44: =min(E44:K44) -> 16.157143 | M44: =MAX(E44:K44) -> 16.157143
B45: =ISOWEEKNUM(C45)-1 -> 34 | C45: =C44+7 -> 46258 | E45: =September!D12 -> 19 | F45: =September!E12 -> 19 | G45: =September!F12 -> 19 | H45: =September!G12 -> 19 | I45: =September!H12 -> 19 | J45: =September!I12 -> 19 | K45: =September!J12 -> 19 | L45: =min(E45:K45) -> 19 | M45: =MAX(E45:K45) -> 19
B46: =ISOWEEKNUM(C46)-1 -> 35 | C46: =C45+7 -> 46265 | E46: =August!D8 -> 16.157143 | F46: =August!E8 -> 16.157143 | G46: =August!F8 -> 16.157143 | H46: =August!G8 -> 16.157143 | I46: =August!H8 -> 16.157143 | J46: =August!I8 -> 16.157143 | K46: =August!J8 -> 16.157143 | L46: =min(E46:K46) -> 16.157143 | M46: =MAX(E46:K46) -> 16.157143
A48: =text(C48,"MMMM") -> September | B48: =ISOWEEKNUM(C48)-1 -> 36 | C48: =C46+7 -> 46272
B49: =ISOWEEKNUM(C49)-1 -> 37 | C49: =C48+7 -> 46279
B50: =ISOWEEKNUM(C50)-1 -> 38 | C50: =C49+7 -> 46286
...

Sheet January
A2: =text(A4,"MMMM") -> January | B2: Week no | C2: Per Week | D2: M | E2: T | F2: W | G2: T | H2: F | I2: S | J2: S | K2: Weekly Min (st) | L2: Weekly Max (st) | M2: Average (st) | N2: Weekly Range (st) | O2: Weekly Change (st) | P2: Weekly Change (lb) | Q2: Weekly Target (st) | R2: Weekly Min (st) | S2: Net Achievement (st) | T2: lb
A4: ='Target-lb'!A4 -> 46027 | B4: =ISOWEEKNUM(A4)-1 -> 1 | C4: ='Your Details'!D5+'Your Details'!E5/14 -> 19 | D4: =C4 -> 19 | E4: =D4 -> 19 | F4: =E4 -> 19 | G4: =F4 -> 19 | H4: =G4 -> 19 | I4: =H4 -> 19 | J4: =I4 -> 19 | K4: =min(D4:J4) -> 19 | L4: =MAX(D4:J4) -> 19 | M4: =AVERAGE(D4:J4) -> 19 | N4: =L4-K4 -> 0 | O4: =J4-D4 -> 0 | P4: =O4*14 -> 0 | Q4: ='Target-st'!C4 -> 18.875 | R4: =K4 -> 19 | S4: =Q4-R4 -> -0.125 | T4: =S4*14 -> -1.75
D5: =D4-C4 -> 0 | E5: =E4-D4 -> 0 | F5: =F4-E4 -> 0 | G5: =G4-F4 -> 0 | H5: =H4-G4 -> 0 | I5: =I4-H4 -> 0 | J5: =J4-I4 -> 0
D6: =D5*14 -> 0 | E6: =E5*14 -> 0 | F6: =F5*14 -> 0 | G6: =G5*14 -> 0 | H6: =H5*14 -> 0 | I6: =I5*14 -> 0 | J6: =J5*14 -> 0
A8: =A4+7 -> 46034 | B8: =B4+1 -> 2 | C8: =J4 -> 19 | D8: =C8 -> 19 | E8: =D8 -> 19 | F8: =E8 -> 19 | G8: =F8 -> 19 | H8: =G8 -> 19 | I8: =H8 -> 19 | J8: =I8 -> 19 | K8: =min(D8:J8) -> 19 | L8: =MAX(D8:J8) -> 19 | M8: =AVERAGE(D8:J8) -> 19 | N8: =L8-K8 -> 0 | O8: =J8-D8 -> 0 | P8: =O8*14 -> 0 | Q8: ='Target-st'!C5 -> 18.75 | R8: =K8 -> 19 | S8: =Q8-R8 -> -0.25 | T8: =S8*14 -> -3.5
D9: =D8-C8 -> 0 | E9: =E8-D8 -> 0 | F9: =F8-E8 -> 0 | G9: =G8-F8 -> 0 | H9: =H8-G8 -> 0 | I9: =I8-H8 -> 0 | J9: =J8-I8 -> 0
D10: =D9*14 -> 0 | E10: =E9*14 -> 0 | F10: =F9*14 -> 0 | G10: =G9*14 -> 0 | H10: =H9*14 -> 0 | I10: =I9*14 -> 0 | J10: =J9*14 -> 0
A12: =A8+7 -> 46041 | B12: =B8+1 -> 3 | C12: =J8 -> 19 | D12: =C12 -> 19 | E12: =D12 -> 19 | F12: =E12 -> 19 | G12: =F12 -> 19 | H12: =G12 -> 19 | I12: =H12 -> 19 | J12: =I12 -> 19 | K12: =min(D12:J12) -> 19 | L12: =MAX(D12:J12) -> 19 | M12: =AVERAGE(D12:J12) -> 19 | N12: =L12-K12 -> 0 | O12: =J12-D12 -> 0 | P12: =O12*14 -> 0 | Q12: ='Target-st'!C6 -> 18.625 | R12: =K12 -> 19 | S12: =Q12-R12 -> -0.375 | T12: =S12*14 -> -5.25
D13: =D12-C12 -> 0 | E13: =E12-D12 -> 0 | F13: =F12-E12 -> 0 | G13: =G12-F12 -> 0 | H13: =H12-G12 -> 0 | I13: =I12-H12 -> 0 | J13: =J12-I12 -> 0
D14: =D13*14 -> 0 | E14: =E13*14 -> 0 | F14: =F13*14 -> 0 | G14: =G13*14 -> 0 | H14: =H13*14 -> 0 | I14: =I13*14 -> 0 | J14: =J13*14 -> 0
A16: =A12+7 -> 46048 | B16: =B12+1 -> 4 | C16: =J12 -> 19 | D16: =C16 -> 19 | E16: =D16 -> 19 | F16: =E16 -> 19 | G16: =F16 -> 19 | H16: =G16 -> 19 | I16: =H16 -> 19 | J16: =I16 -> 19 | K16: =min(D16:J16) -> 19 | L16: =MAX(D16:J16) -> 19 | M16: =AVERAGE(D16:J16) -> 19 | N16: =L16-K16 -> 0 | O16: =J16-D16 -> 0 | P16: =O16*14 -> 0 | Q16: ='Target-st'!C7 -> 18.5 | R16: =K16 -> 19 | S16: =Q16-R16 -> -0.5 | T16: =S16*14 -> -7
D17: =D16-C16 -> 0 | E17: =E16-D16 -> 0 | F17: =F16-E16 -> 0 | G17: =G16-F16 -> 0 | H17: =H16-G16 -> 0 | I17: =I16-H16 -> 0 | J17: =J16-I16 -> 0
D18: =D17*14 -> 0 | E18: =E17*14 -> 0 | F18: =F17*14 -> 0 | G18: =G17*14 -> 0 | H18: =H17*14 -> 0 | I18: =I17*14 -> 0 | J18: =J17*14 -> 0

Sheet February
A2: =text(A4,"MMMM") -> February | B2: Week no | C2: Per Week | D2: M | E2: T | F2: W | G2: T | H2: F | I2: S | J2: S | K2: Weekly Min (st) | L2: Weekly Max (st) | M2: Average (st) | N2: Weekly Range (st) | O2: Weekly Change (st) | P2: Weekly Change (lb) | Q2: Weekly Target (st) | R2: Weekly Min (st) | S2: Net Achievement (st) | T2: lb
A4: =January!A16+7 -> 46055 | B4: =ISOWEEKNUM(A4)-1 -> 5 | C4: =January!J16 -> 19 | D4: =C4 -> 19 | E4: =D4 -> 19 | F4: =E4 -> 19 | G4: =F4 -> 19 | H4: =G4 -> 19 | I4: =H4 -> 19 | J4: =I4 -> 19 | K4: =min(D4:J4) -> 19 | L4: =MAX(D4:J4) -> 19 | M4: =AVERAGE(D4:J4) -> 19 | N4: =L4-K4 -> 0 | O4: =J4-D4 -> 0 | P4: =O4*14 -> 0 | Q4: ='Target-st'!D9 -> 18.375 | R4: =K4 -> 19 | S4: =Q4-R4 -> -0.625 | T4: =S4*14 -> -8.75
D5: =D4-C4 -> 0 | E5: =E4-D4 -> 0 | F5: =F4-E4 -> 0 | G5: =G4-F4 -> 0 | H5: =H4-G4 -> 0 | I5: =I4-H4 -> 0 | J5: =J4-I4 -> 0
D6: =D5*14 -> 0 | E6: =E5*14 -> 0 | F6: =F5*14 -> 0 | G6: =G5*14 -> 0 | H6: =H5*14 -> 0 | I6: =I5*14 -> 0 | J6: =J5*14 -> 0
A8: =A4+7 -> 46062 | B8: =B4+1 -> 6 | C8: =J4 -> 19 | D8: =C8 -> 19 | E8: =D8 -> 19 | F8: =E8 -> 19 | G8: =F8 -> 19 | H8: =G8 -> 19 | I8: =H8 -> 19 | J8: =I8 -> 19 | K8: =min(D8:J8) -> 19 | L8: =MAX(D8:J8) -> 19 | M8: =AVERAGE(D8:J8) -> 19 | N8: =L8-K8 -> 0 | O8: =J8-D8 -> 0 | P8: =O8*14 -> 0 | Q8: ='Target-st'!D10 -> 18.25 | R8: =K8 -> 19 | S8: =Q8-R8 -> -0.75 | T8: =S8*14 -> -10.5
D9: =D8-C8 -> 0 | E9: =E8-D8 -> 0 | F9: =F8-E8 -> 0 | G9: =G8-F8 -> 0 | H9: =H8-G8 -> 0 | I9: =I8-H8 -> 0 | J9: =J8-I8 -> 0
D10: =D9*14 -> 0 | E10: =E9*14 -> 0 | F10: =F9*14 -> 0 | G10: =G9*14 -> 0 | H10: =H9*14 -> 0 | I10: =I9*14 -> 0 | J10: =J9*14 -> 0
A12: =A8+7 -> 46069 | B12: =B8+1 -> 7 | C12: =J8 -> 19 | D12: =C12 -> 19 | E12: =D12 -> 19 | F12: =E12 -> 19 | G12: =F12 -> 19 | H12: =G12 -> 19 | I12: =H12 -> 19 | J12: =I12 -> 19 | K12: =min(D12:J12) -> 19 | L12: =MAX(D12:J12) -> 19 | M12: =AVERAGE(D12:J12) -> 19 | N12: =L12-K12 -> 0 | O12: =J12-D12 -> 0 | P12: =O12*14 -> 0 | Q12: ='Target-st'!D11 -> 18.125 | R12: =K12 -> 19 | S12: =Q12-R12 -> -0.875 | T12: =S12*14 -> -12.25
D13: =D12-C12 -> 0 | E13: =E12-D12 -> 0 | F13: =F12-E12 -> 0 | G13: =G12-F12 -> 0 | H13: =H12-G12 -> 0 | I13: =I12-H12 -> 0 | J13: =J12-I12 -> 0
D14: =D13*14 -> 0 | E14: =E13*14 -> 0 | F14: =F13*14 -> 0 | G14: =G13*14 -> 0 | H14: =H13*14 -> 0 | I14: =I13*14 -> 0 | J14: =J13*14 -> 0
A16: =A12+7 -> 46076 | B16: =B12+1 -> 8 | C16: =J12 -> 19 | D16: =C16 -> 19 | E16: =D16 -> 19 | F16: =E16 -> 19 | G16: =F16 -> 19 | H16: =G16 -> 19 | I16: =H16 -> 19 | J16: =I16 -> 19 | K16: =min(D16:J16) -> 19 | L16: =MAX(D16:J16) -> 19 | M16: =AVERAGE(D16:J16) -> 19 | N16: =L16-K16 -> 0 | O16: =J16-D16 -> 0 | P16: =O16*14 -> 0 | Q16: ='Target-st'!D12 -> 18 | R16: =K16 -> 19 | S16: =Q16-R16 -> -1 | T16: =S16*14 -> -14
D17: =D16-C16 -> 0 | E17: =E16-D16 -> 0 | F17: =F16-E16 -> 0 | G17: =G16-F16 -> 0 | H17: =H16-G16 -> 0 | I17: =I16-H16 -> 0 | J17: =J16-I16 -> 0
D18: =D17*14 -> 0 | E18: =E17*14 -> 0 | F18: =F17*14 -> 0 | G18: =G17*14 -> 0 | H18: =H17*14 -> 0 | I18: =I17*14 -> 0 | J18: =J17*14 -> 0

Sheet March
A2: =text(A4,"MMMM") -> March | B2: Week no | C2: Per Week | D2: M | E2: T | F2: W | G2: T | H2: F | I2: S | J2: S | K2: Weekly Min (st) | L2: Weekly Max (st) | M2: Average (st) | N2: Weekly Range (st) | O2: Weekly Change (st) | P2: Weekly Change (lb) | Q2: Weekly Target (st) | R2: Weekly Min (st) | S2: Net Achievement (st) | T2: lb
A4: =February!A16+7 -> 46083 | B4: =ISOWEEKNUM(A4)-1 -> 9 | C4: =February!J16 -> 19 | D4: =C4 -> 19 | E4: =D4 -> 19 | F4: =E4 -> 19 | G4: =F4 -> 19 | H4: =G4 -> 19 | I4: =H4 -> 19 | J4: =I4 -> 19 | K4: =min(D4:J4) -> 19 | L4: =MAX(D4:J4) -> 19 | M4: =AVERAGE(D4:J4) -> 19 | N4: =L4-K4 -> 0 | O4: =J4-D4 -> 0 | P4: =O4*14 -> 0 | Q4: ='Target-st'!E14 -> 17.875 | R4: =K4 -> 19 | S4: =Q4-R4 -> -1.125 | T4: =S4*14 -> -15.75
D5: =D4-C4 -> 0 | E5: =E4-D4 -> 0 | F5: =F4-E4 -> 0 | G5: =G4-F4 -> 0 | H5: =H4-G4 -> 0 | I5: =I4-H4 -> 0 | J5: =J4-I4 -> 0
D6: =D5*14 -> 0 | E6: =E5*14 -> 0 | F6: =F5*14 -> 0 | G6: =G5*14 -> 0 | H6: =H5*14 -> 0 | I6: =I5*14 -> 0 | J6: =J5*14 -> 0
A8: =A4+7 -> 46090 | B8: =B4+1 -> 10 | C8: =J4 -> 19 | D8: =C8 -> 19 | E8: =D8 -> 19 | F8: =E8 -> 19 | G8: =F8 -> 19 | H8: =G8 -> 19 | I8: =H8 -> 19 | J8: =I8 -> 19 | K8: =min(D8:J8) -> 19 | L8: =MAX(D8:J8) -> 19 | M8: =AVERAGE(D8:J8) -> 19 | N8: =L8-K8 -> 0 | O8: =J8-D8 -> 0 | P8: =O8*14 -> 0 | Q8: ='Target-st'!E15 -> 17.75 | R8: =K8 -> 19 | S8: =Q8-R8 -> -1.25 | T8: =S8*14 -> -17.5
D9: =D8-C8 -> 0 | E9: =E8-D8 -> 0 | F9: =F8-E8 -> 0 | G9: =G8-F8 -> 0 | H9: =H8-G8 -> 0 | I9: =I8-H8 -> 0 | J9: =J8-I8 -> 0
D10: =D9*14 -> 0 | E10: =E9*14 -> 0 | F10: =F9*14 -> 0 | G10: =G9*14 -> 0 | H10: =H9*14 -> 0 | I10: =I9*14 -> 0 | J10: =J9*14 -> 0
A12: =A8+7 -> 46097 | B12: =B8+1 -> 11 | C12: =J8 -> 19 | D12: =C12 -> 19 | E12: =D12 -> 19 | F12: =E12 -> 19 | G12: =F12 -> 19 | H12: =G12 -> 19 | I12: =H12 -> 19 | J12: =I12 -> 19 | K12: =min(D12:J12) -> 19 | L12: =MAX(D12:J12) -> 19 | M12: =AVERAGE(D12:J12) -> 19 | N12: =L12-K12 -> 0 | O12: =J12-D12 -> 0 | P12: =O12*14 -> 0 | Q12: ='Target-st'!E16 -> 17.625 | R12: =K12 -> 19 | S12: =Q12-R12 -> -1.375 | T12: =S12*14 -> -19.25
D13: =D12-C12 -> 0 | E13: =E12-D12 -> 0 | F13: =F12-E12 -> 0 | G13: =G12-F12 -> 0 | H13: =H12-G12 -> 0 | I13: =I12-H12 -> 0 | J13: =J12-I12 -> 0
D14: =D13*14 -> 0 | E14: =E13*14 -> 0 | F14: =F13*14 -> 0 | G14: =G13*14 -> 0 | H14: =H13*14 -> 0 | I14: =I13*14 -> 0 | J14: =J13*14 -> 0
A16: =A12+7 -> 46104 | B16: =B12+1 -> 12 | C16: =J12 -> 19 | D16: =C16 -> 19 | E16: =D16 -> 19 | F16: =E16 -> 19 | G16: =F16 -> 19 | H16: =G16 -> 19 | I16: =H16 -> 19 | J16: =I16 -> 19 | K16: =min(D16:J16) -> 19 | L16: =MAX(D16:J16) -> 19 | M16: =AVERAGE(D16:J16) -> 19 | N16: =L16-K16 -> 0 | O16: =J16-D16 -> 0 | P16: =O16*14 -> 0 | Q16: ='Target-st'!E17 -> 17.5 | R16: =K16 -> 19 | S16: =Q16-R16 -> -1.5 | T16: =S16*14 -> -21
D17: =D16-C16 -> 0 | E17: =E16-D16 -> 0 | F17: =F16-E16 -> 0 | G17: =G16-F16 -> 0 | H17: =H16-G16 -> 0 | I17: =I16-H16 -> 0 | J17: =J16-I16 -> 0
D18: =D17*14 -> 0 | E18: =E17*14 -> 0 | F18: =F17*14 -> 0 | G18: =G17*14 -> 0 | H18: =H17*14 -> 0 | I18: =I17*14 -> 0 | J18: =J17*14 -> 0

Sheet April
A2: =text(A8,"MMMM") -> April | B2: Week no | C2: Per Week | D2: M | E2: T | F2: W | G2: T | H2: F | I2: S | J2: S | K2: Weekly Min (st) | L2: Weekly Max (st) | M2: Average (st) | N2: Weekly Range (st) | O2: Weekly Change (st) | P2: Weekly Change (lb) | Q2: Weekly Target (st) | R2: Weekly Min (st) | S2: Net Achievement (st) | T2: lb
A4: =March!A16+7 -> 46111 | B4: =ISOWEEKNUM(A4)-1 -> 13 | C4: =March!J16 -> 19 | D4: =C4 -> 19 | E4: =D4 -> 19 | F4: =E4 -> 19 | G4: =F4 -> 19 | H4: =G4 -> 19 | I4: =H4 -> 19 | J4: =I4 -> 19 | K4: =min(D4:J4) -> 19 | L4: =MAX(D4:J4) -> 19 | M4: =AVERAGE(D4:J4) -> 19 | N4: =L4-K4 -> 0 | O4: =J4-D4 -> 0 | P4: =O4*14 -> 0 | Q4: ='Target-st'!F19 -> 17.625 | R4: =K4 -> 19 | S4: =Q4-R4 -> -1.375 | T4: =S4*14 -> -19.25
D5: =D4-C4 -> 0 | E5: =E4-D4 -> 0 | F5: =F4-E4 -> 0 | G5: =G4-F4 -> 0 | H5: =H4-G4 -> 0 | I5: =I4-H4 -> 0 | J5: =J4-I4 -> 0
D6: =D5*14 -> 0 | E6: =E5*14 -> 0 | F6: =F5*14 -> 0 | G6: =G5*14 -> 0 | H6: =H5*14 -> 0 | I6: =I5*14 -> 0 | J6: =J5*14 -> 0
A8: =A4+7 -> 46118 | B8: =B4+1 -> 14 | C8: =J4 -> 19 | D8: =C8 -> 19 | E8: =D8 -> 19 | F8: =E8 -> 19 | G8: =F8 -> 19 | H8: =G8 -> 19 | I8: =H8 -> 19 | J8: =I8 -> 19 | K8: =min(D8:J8) -> 19 | L8: =MAX(D8:J8) -> 19 | M8: =AVERAGE(D8:J8) -> 19 | N8: =L8-K8 -> 0 | O8: =J8-D8 -> 0 | P8: =O8*14 -> 0 | Q8: ='Target-st'!F20 -> 17.5 | R8: =K8 -> 19 | S8: =Q8-R8 -> -1.5 | T8: =S8*14 -> -21
D9: =D8-C8 -> 0 | E9: =E8-D8 -> 0 | F9: =F8-E8 -> 0 | G9: =G8-F8 -> 0 | H9: =H8-G8 -> 0 | I9: =I8-H8 -> 0 | J9: =J8-I8 -> 0
D10: =D9*14 -> 0 | E10: =E9*14 -> 0 | F10: =F9*14 -> 0 | G10: =G9*14 -> 0 | H10: =H9*14 -> 0 | I10: =I9*14 -> 0 | J10: =J9*14 -> 0
A12: =A8+7 -> 46125 | B12: =B8+1 -> 15 | C12: =J8 -> 19 | D12: =C12 -> 19 | E12: =D12 -> 19 | F12: =E12 -> 19 | G12: =F12 -> 19 | H12: =G12 -> 19 | I12: =H12 -> 19 | J12: =I12 -> 19 | K12: =min(D12:J12) -> 19 | L12: =MAX(D12:J12) -> 19 | M12: =AVERAGE(D12:J12) -> 19 | N12: =L12-K12 -> 0 | O12: =J12-D12 -> 0 | P12: =O12*14 -> 0 | Q12: ='Target-st'!F21 -> 17.375 | R12: =K12 -> 19 | S12: =Q12-R12 -> -1.625 | T12: =S12*14 -> -22.75
D13: =D12-C12 -> 0 | E13: =E12-D12 -> 0 | F13: =F12-E12 -> 0 | G13: =G12-F12 -> 0 | H13: =H12-G12 -> 0 | I13: =I12-H12 -> 0 | J13: =J12-I12 -> 0
D14: =D13*14 -> 0 | E14: =E13*14 -> 0 | F14: =F13*14 -> 0 | G14: =G13*14 -> 0 | H14: =H13*14 -> 0 | I14: =I13*14 -> 0 | J14: =J13*14 -> 0
A16: =A12+7 -> 46132 | B16: =B12+1 -> 16 | C16: =J12 -> 19 | D16: =C16 -> 19 | E16: =D16 -> 19 | F16: =E16 -> 19 | G16: =F16 -> 19 | H16: =G16 -> 19 | I16: =H16 -> 19 | J16: =I16 -> 19 | K16: =min(D16:J16) -> 19 | L16: =MAX(D16:J16) -> 19 | M16: =AVERAGE(D16:J16) -> 19 | N16: =L16-K16 -> 0 | O16: =J16-D16 -> 0 | P16: =O16*14 -> 0 | Q16: ='Target-st'!F22 -> 17.25 | R16: =K16 -> 19 | S16: =Q16-R16 -> -1.75 | T16: =S16*14 -> -24.5
D17: =D16-C16 -> 0 | E17: =E16-D16 -> 0 | F17: =F16-E16 -> 0 | G17: =G16-F16 -> 0 | H17: =H16-G16 -> 0 | I17: =I16-H16 -> 0 | J17: =J16-I16 -> 0
D18: =D17*14 -> 0 | E18: =E17*14 -> 0 | F18: =F17*14 -> 0 | G18: =G17*14 -> 0 | H18: =H17*14 -> 0 | I18: =I17*14 -> 0 | J18: =J17*14 -> 0
A20: =A16+7 -> 46139 | B20: =B16+1 -> 17 | C20: =J16 -> 19 | D20: =C20 -> 19 | E20: =D20 -> 19 | F20: =E20 -> 19 | G20: =F20 -> 19 | H20: =G20 -> 19 | I20: =H20 -> 19 | J20: =I20 -> 19 | K20: =min(D20:J20) -> 19 | L20: =MAX(D20:J20) -> 19 | M20: =AVERAGE(D20:J20) -> 19 | N20: =L20-K20 -> 0 | O20: =J20-D20 -> 0 | P20: =O20*14 -> 0 | Q20: ='Target-st'!F23 -> 17.125 | R20: =K20 -> 19 | S20: =Q20-R20 -> -1.875 | T20: =S20*14 -> -26.25
D21: =D20-C20 -> 0 | E21: =E20-D20 -> 0 | F21: =F20-E20 -> 0 | G21: =G20-F20 -> 0 | H21: =H20-G20 -> 0 | I21: =I20-H20 -> 0 | J21: =J20-I20 -> 0
D22: =D21*14 -> 0 | E22: =E21*14 -> 0 | F22: =F21*14 -> 0 | G22: =G21*14 -> 0 | H22: =H21*14 -> 0 | I22: =I21*14 -> 0 | J22: =J21*14 -> 0

Sheet May
A2: =text(A4,"MMMM") -> May | B2: Week no | C2: Per Week | D2: M | E2: T | F2: W | G2: T | H2: F | I2: S | J2: S | K2: Weekly Min (st) | L2: Weekly Max (st) | M2: Average (st) | N2: Weekly Range (st) | O2: Weekly Change (st) | P2: Weekly Change (lb) | Q2: Weekly Target (st) | R2: Weekly Min (st) | S2: Net Achievement (st) | T2: lb
A4: =April!A20+7 -> 46146 | B4: =ISOWEEKNUM(A4)-1 -> 18 | C4: =April!J20 -> 19 | D4: =C4 -> 19 | E4: =D4 -> 19 | F4: =E4 -> 19 | G4: =F4 -> 19 | H4: =G4 -> 19 | I4: =H4 -> 19 | J4: =I4 -> 19 | K4: =min(D4:J4) -> 19 | L4: =MAX(D4:J4) -> 19 | M4: =AVERAGE(D4:J4) -> 19 | N4: =L4-K4 -> 0 | O4: =J4-D4 -> 0 | P4: =O4*14 -> 0 | Q4: ='Target-st'!G25 -> 17 | R4: =K4 -> 19 | S4: =Q4-R4 -> -2 | T4: =S4*14 -> -28
D5: =D4-C4 -> 0 | E5: =E4-D4 -> 0 | F5: =F4-E4 -> 0 | G5: =G4-F4 -> 0 | H5: =H4-G4 -> 0 | I5: =I4-H4 -> 0 | J5: =J4-I4 -> 0
D6: =D5*14 -> 0 | E6: =E5*14 -> 0 | F6: =F5*14 -> 0 | G6: =G5*14 -> 0 | H6: =H5*14 -> 0 | I6: =I5*14 -> 0 | J6: =J5*14 -> 0
A8: =A4+7 -> 46153 | B8: =B4+1 -> 19 | C8: =J4 -> 19 | D8: =C8 -> 19 | E8: =D8 -> 19 | F8: =E8 -> 19 | G8: =F8 -> 19 | H8: =G8 -> 19 | I8: =H8 -> 19 | J8: =I8 -> 19 | K8: =min(D8:J8) -> 19 | L8: =MAX(D8:J8) -> 19 | M8: =AVERAGE(D8:J8) -> 19 | N8: =L8-K8 -> 0 | O8: =J8-D8 -> 0 | P8: =O8*14 -> 0 | Q8: ='Target-st'!G26 -> 16.875 | R8: =K8 -> 19 | S8: =Q8-R8 -> -2.125 | T8: =S8*14 -> -29.75
D9: =D8-C8 -> 0 | E9: =E8-D8 -> 0 | F9: =F8-E8 -> 0 | G9: =G8-F8 -> 0 | H9: =H8-G8 -> 0 | I9: =I8-H8 -> 0 | J9: =J8-I8 -> 0
D10: =D9*14 -> 0 | E10: =E9*14 -> 0 | F10: =F9*14 -> 0 | G10: =G9*14 -> 0 | H10: =H9*14 -> 0 | I10: =I9*14 -> 0 | J10: =J9*14 -> 0
A12: =A8+7 -> 46160 | B12: =B8+1 -> 20 | C12: =J8 -> 19 | D12: =C12 -> 19 | E12: =D12 -> 19 | F12: =E12 -> 19 | G12: =F12 -> 19 | H12: =G12 -> 19 | I12: =H12 -> 19 | J12: =I12 -> 19 | K12: =min(D12:J12) -> 19 | L12: =MAX(D12:J12) -> 19 | M12: =AVERAGE(D12:J12) -> 19 | N12: =L12-K12 -> 0 | O12: =J12-D12 -> 0 | P12: =O12*14 -> 0 | Q12: ='Target-st'!G27 -> 16.75 | R12: =K12 -> 19 | S12: =Q12-R12 -> -2.25 | T12: =S12*14 -> -31.5
D13: =D12-C12 -> 0 | E13: =E12-D12 -> 0 | F13: =F12-E12 -> 0 | G13: =G12-F12 -> 0 | H13: =H12-G12 -> 0 | I13: =I12-H12 -> 0 | J13: =J12-I12 -> 0 | Q13: ='Target-st'!G29
D14: =D13*14 -> 0 | E14: =E13*14 -> 0 | F14: =F13*14 -> 0 | G14: =G13*14 -> 0 | H14: =H13*14 -> 0 | I14: =I13*14 -> 0 | J14: =J13*14 -> 0
A16: =A12+7 -> 46167 | B16: =B12+1 -> 21 | C16: =J12 -> 19 | D16: =C16 -> 19 | E16: =D16 -> 19 | F16: =E16 -> 19 | G16: =F16 -> 19 | H16: =G16 -> 19 | I16: =H16 -> 19 | J16: =I16 -> 19 | K16: =min(D16:J16) -> 19 | L16: =MAX(D16:J16) -> 19 | M16: =AVERAGE(D16:J16) -> 19 | N16: =L16-K16 -> 0 | O16: =J16-D16 -> 0 | P16: =O16*14 -> 0 | Q16: ='Target-st'!G28 -> 16.625 | R16: =K16 -> 19 | S16: =Q16-R16 -> -2.375 | T16: =S16*14 -> -33.25
D17: =D16-C16 -> 0 | E17: =E16-D16 -> 0 | F17: =F16-E16 -> 0 | G17: =G16-F16 -> 0 | H17: =H16-G16 -> 0 | I17: =I16-H16 -> 0 | J17: =J16-I16 -> 0
D18: =D17*14 -> 0 | E18: =E17*14 -> 0 | F18: =F17*14 -> 0 | G18: =G17*14 -> 0 | H18: =H17*14 -> 0 | I18: =I17*14 -> 0 | J18: =J17*14 -> 0

Sheet June
A2: =text(A4,"MMMM") -> June | B2: Week no | C2: Per Week | D2: M | E2: T | F2: W | G2: T | H2: F | I2: S | J2: S | K2: Weekly Min (st) | L2: Weekly Max (st) | M2: Average (st) | N2: Weekly Range (st) | O2: Weekly Change (st) | P2: Weekly Change (lb) | Q2: Weekly Target (st) | R2: Weekly Min (st) | S2: Net Achievement (st) | T2: lb
A4: =May!A16+7 -> 46174 | B4: =ISOWEEKNUM(A4)-1 -> 22 | C4: 16.5 | D4: =C4 -> 16.5 | E4: =D4 -> 16.5 | F4: =E4 -> 16.5 | G4: =F4 -> 16.5 | H4: =G4 -> 16.5 | I4: =H4 -> 16.5 | J4: =I4 -> 16.5 | K4: =min(D4:J4) -> 16.5 | L4: =MAX(D4:J4) -> 16.5 | M4: =AVERAGE(D4:J4) -> 16.5 | N4: =L4-K4 -> 0 | O4: =J4-D4 -> 0 | P4: =O4*14 -> 0 | Q4: ='Target-st'!H30 -> 16.5 | R4: =K4 -> 16.5 | S4: =Q4-R4 -> 0 | T4: =S4*14 -> 0
D5: =D4-C4 -> 0 | E5: =E4-D4 -> 0 | F5: =F4-E4 -> 0 | G5: =G4-F4 -> 0 | H5: =H4-G4 -> 0 | I5: =I4-H4 -> 0 | J5: =J4-I4 -> 0
D6: =D5*14 -> 0 | E6: =E5*14 -> 0 | F6: =F5*14 -> 0 | G6: =G5*14 -> 0 | H6: =H5*14 -> 0 | I6: =I5*14 -> 0 | J6: =J5*14 -> 0
A8: =A4+7 -> 46181 | B8: =B4+1 -> 23 | C8: =J4 -> 16.5 | D8: =C8 -> 16.5 | E8: =D8 -> 16.5 | F8: =E8 -> 16.5 | G8: =F8 -> 16.5 | H8: =G8 -> 16.5 | I8: =H8 -> 16.5 | J8: =I8 -> 16.5 | K8: =min(D8:J8) -> 16.5 | L8: =MAX(D8:J8) -> 16.5 | M8: =AVERAGE(D8:J8) -> 16.5 | N8: =L8-K8 -> 0 | O8: =J8-D8 -> 0 | P8: =O8*14 -> 0 | Q8: ='Target-st'!H31 -> 16.375 | R8: =K8 -> 16.5 | S8: =Q8-R8 -> -0.125 | T8: =S8*14 -> -1.75
D9: =D8-C8 -> 0 | E9: =E8-D8 -> 0 | F9: =F8-E8 -> 0 | G9: =G8-F8 -> 0 | H9: =H8-G8 -> 0 | I9: =I8-H8 -> 0 | J9: =J8-I8 -> 0
D10: =D9*14 -> 0 | E10: =E9*14 -> 0 | F10: =F9*14 -> 0 | G10: =G9*14 -> 0 | H10: =H9*14 -> 0 | I10: =I9*14 -> 0 | J10: =J9*14 -> 0
A12: =A8+7 -> 46188 | B12: =B8+1 -> 24 | C12: =J8 -> 16.5 | D12: =C12 -> 16.5 | E12: =D12 -> 16.5 | F12: =E12 -> 16.5 | G12: =F12 -> 16.5 | H12: =16+2.2/14 -> 16.157143 | I12: =H12 -> 16.157143 | J12: =I12 -> 16.157143 | K12: =min(D12:J12) -> 16.157143 | L12: =MAX(D12:J12) -> 16.5 | M12: =AVERAGE(D12:J12) -> 16.353061 | N12: =L12-K12 -> 0.34285714 | O12: =J12-D12 -> -0.34285714 | P12: =O12*14 -> -4.8 | Q12: ='Target-st'!H32 -> 16.25 | R12: =K12 -> 16.157143 | S12: =Q12-R12 -> 0.092857143 | T12: =S12*14 -> 1.3
D13: =D12-C12 -> 0 | E13: =E12-D12 -> 0 | F13: =F12-E12 -> 0 | G13: =G12-F12 -> 0 | H13: =H12-G12 -> -0.34285714 | I13: =I12-H12 -> 0 | J13: =J12-I12 -> 0 | Q13: ='Target-st'!G29
D14: =D13*14 -> 0 | E14: =E13*14 -> 0 | F14: =F13*14 -> 0 | G14: =G13*14 -> 0 | H14: =H13*14 -> -4.8 | I14: =I13*14 -> 0 | J14: =J13*14 -> 0
A16: =A12+7 -> 46195 | B16: =B12+1 -> 25 | C16: =J12 -> 16.157143 | D16: =C16 -> 16.157143 | E16: =D16 -> 16.157143 | F16: =E16 -> 16.157143 | G16: =F16 -> 16.157143 | H16: =G16 -> 16.157143 | I16: =H16 -> 16.157143 | J16: =I16 -> 16.157143 | K16: =min(D16:J16) -> 16.157143 | L16: =MAX(D16:J16) -> 16.157143 | M16: =AVERAGE(D16:J16) -> 16.157143 | N16: =L16-K16 -> 0 | O16: =J16-D16 -> 0 | P16: =O16*14 -> 0 | Q16: ='Target-st'!H33 -> 16.125 | R16: =K16 -> 16.157143 | S16: =Q16-R16 -> -0.032142857 | T16: =S16*14 -> -0.45
D17: =D16-C16 -> 0 | E17: =E16-D16 -> 0 | F17: =F16-E16 -> 0 | G17: =G16-F16 -> 0 | H17: =H16-G16 -> 0 | I17: =I16-H16 -> 0 | J17: =J16-I16 -> 0
D18: =D17*14 -> 0 | E18: =E17*14 -> 0 | F18: =F17*14 -> 0 | G18: =G17*14 -> 0 | H18: =H17*14 -> 0 | I18: =I17*14 -> 0 | J18: =J17*14 -> 0
A20: =A16+7 -> 46202 | B20: =B16+1 -> 26 | C20: =J16 -> 16.157143 | D20: =C20 -> 16.157143 | E20: =D20 -> 16.157143 | F20: =E20 -> 16.157143 | G20: =F20 -> 16.157143 | H20: =G20 -> 16.157143 | I20: =H20 -> 16.157143 | J20: =I20 -> 16.157143 | K20: =min(D20:J20) -> 16.157143 | L20: =MAX(D20:J20) -> 16.157143 | M20: =AVERAGE(D20:J20) -> 16.157143 | N20: =L20-K20 -> 0 | O20: =J20-D20 -> 0 | P20: =O20*14 -> 0 | Q20: ='Target-st'!H34 -> 16 | R20: =K20 -> 16.157143 | S20: =Q20-R20 -> -0.15714286 | T20: =S20*14 -> -2.2
D21: =D20-C20 -> 0 | E21: =E20-D20 -> 0 | F21: =F20-E20 -> 0 | G21: =G20-F20 -> 0 | H21: =H20-G20 -> 0 | I21: =I20-H20 -> 0 | J21: =J20-I20 -> 0
D22: =D21*14 -> 0 | E22: =E21*14 -> 0 | F22: =F21*14 -> 0 | G22: =G21*14 -> 0 | H22: =H21*14 -> 0 | I22: =I21*14 -> 0 | J22: =J21*14 -> 0

Sheet July
A2: =text(A4,"MMMM") -> July | B2: Week no | C2: Per Week | D2: M | E2: T | F2: W | G2: T | H2: F | I2: S | J2: S | K2: Weekly Min (st) | L2: Weekly Max (st) | M2: Average (st) | N2: Weekly Range (st) | O2: Weekly Change (st) | P2: Weekly Change (lb) | Q2: Weekly Target (st) | R2: Weekly Min (st) | S2: Net Achievement (st) | T2: lb
A4: =June!A20+7 -> 46209 | B4: =ISOWEEKNUM(A4)-1 -> 27 | C4: =June!J20 -> 16.157143 | D4: =C4 -> 16.157143 | E4: =D4 -> 16.157143 | F4: =E4 -> 16.157143 | G4: =F4 -> 16.157143 | H4: =G4 -> 16.157143 | I4: =H4 -> 16.157143 | J4: =I4 -> 16.157143 | K4: =min(D4:J4) -> 16.157143 | L4: =MAX(D4:J4) -> 16.157143 | M4: =AVERAGE(D4:J4) -> 16.157143 | N4: =L4-K4 -> 0 | O4: =J4-D4 -> 0 | P4: =O4*14 -> 0 | Q4: ='Target-st'!I36 -> 15.875 | R4: =K4 -> 16.157143 | S4: =Q4-R4 -> -0.28214286 | T4: =S4*14 -> -3.95
D5: =D4-C4 -> 0 | E5: =E4-D4 -> 0 | F5: =F4-E4 -> 0 | G5: =G4-F4 -> 0 | H5: =H4-G4 -> 0 | I5: =I4-H4 -> 0 | J5: =J4-I4 -> 0
D6: =D5*14 -> 0 | E6: =E5*14 -> 0 | F6: =F5*14 -> 0 | G6: =G5*14 -> 0 | H6: =H5*14 -> 0 | I6: =I5*14 -> 0 | J6: =J5*14 -> 0
A8: =A4+7 -> 46216 | B8: =B4+1 -> 28 | C8: =J4 -> 16.157143 | D8: =C8 -> 16.157143 | E8: =D8 -> 16.157143 | F8: =E8 -> 16.157143 | G8: =F8 -> 16.157143 | H8: =G8 -> 16.157143 | I8: =H8 -> 16.157143 | J8: =I8 -> 16.157143 | K8: =min(D8:J8) -> 16.157143 | L8: =MAX(D8:J8) -> 16.157143 | M8: =AVERAGE(D8:J8) -> 16.157143 | N8: =L8-K8 -> 0 | O8: =J8-D8 -> 0 | P8: =O8*14 -> 0 | Q8: ='Target-st'!I37 -> 15.75 | R8: =K8 -> 16.157143 | S8: =Q8-R8 -> -0.40714286 | T8: =S8*14 -> -5.7
D9: =D8-C8 -> 0 | E9: =E8-D8 -> 0 | F9: =F8-E8 -> 0 | G9: =G8-F8 -> 0 | H9: =H8-G8 -> 0 | I9: =I8-H8 -> 0 | J9: =J8-I8 -> 0
D10: =D9*14 -> 0 | E10: =E9*14 -> 0 | F10: =F9*14 -> 0 | G10: =G9*14 -> 0 | H10: =H9*14 -> 0 | I10: =I9*14 -> 0 | J10: =J9*14 -> 0
A12: =A8+7 -> 46223 | B12: =B8+1 -> 29 | C12: =J8 -> 16.157143 | D12: =C12 -> 16.157143 | E12: =D12 -> 16.157143 | F12: =E12 -> 16.157143 | G12: =F12 -> 16.157143 | H12: =G12 -> 16.157143 | I12: =H12 -> 16.157143 | J12: =I12 -> 16.157143 | K12: =min(D12:J12) -> 16.157143 | L12: =MAX(D12:J12) -> 16.157143 | M12: =AVERAGE(D12:J12) -> 16.157143 | N12: =L12-K12 -> 0 | O12: =J12-D12 -> 0 | P12: =O12*14 -> 0 | Q12: ='Target-st'!I38 -> 15.625 | R12: =K12 -> 16.157143 | S12: =Q12-R12 -> -0.53214286 | T12: =S12*14 -> -7.45
D13: =D12-C12 -> 0 | E13: =E12-D12 -> 0 | F13: =F12-E12 -> 0 | G13: =G12-F12 -> 0 | H13: =H12-G12 -> 0 | I13: =I12-H12 -> 0 | J13: =J12-I12 -> 0 | Q13: ='Target-st'!G29
D14: =D13*14 -> 0 | E14: =E13*14 -> 0 | F14: =F13*14 -> 0 | G14: =G13*14 -> 0 | H14: =H13*14 -> 0 | I14: =I13*14 -> 0 | J14: =J13*14 -> 0
A16: =A12+7 -> 46230 | B16: =B12+1 -> 30 | C16: =J12 -> 16.157143 | D16: =C16 -> 16.157143 | E16: =D16 -> 16.157143 | F16: =E16 -> 16.157143 | G16: =F16 -> 16.157143 | H16: =G16 -> 16.157143 | I16: =H16 -> 16.157143 | J16: =I16 -> 16.157143 | K16: =min(D16:J16) -> 16.157143 | L16: =MAX(D16:J16) -> 16.157143 | M16: =AVERAGE(D16:J16) -> 16.157143 | N16: =L16-K16 -> 0 | O16: =J16-D16 -> 0 | P16: =O16*14 -> 0 | Q16: ='Target-st'!I39 -> 15.5 | R16: =K16 -> 16.157143 | S16: =Q16-R16 -> -0.65714286 | T16: =S16*14 -> -9.2
D17: =D16-C16 -> 0 | E17: =E16-D16 -> 0 | F17: =F16-E16 -> 0 | G17: =G16-F16 -> 0 | H17: =H16-G16 -> 0 | I17: =I16-H16 -> 0 | J17: =J16-I16 -> 0
D18: =D17*14 -> 0 | E18: =E17*14 -> 0 | F18: =F17*14 -> 0 | G18: =G17*14 -> 0 | H18: =H17*14 -> 0 | I18: =I17*14 -> 0 | J18: =J17*14 -> 0

Sheet August
A2: =text(A4,"MMMM") -> August | B2: Week no | C2: Per Week | D2: M | E2: T | F2: W | G2: T | H2: F | I2: S | J2: S | K2: Weekly Min (st) | L2: Weekly Max (st) | M2: Average (st) | N2: Weekly Range (st) | O2: Weekly Change (st) | P2: Weekly Change (lb) | Q2: Weekly Target (st) | R2: Weekly Min (st) | S2: Net Achievement (st) | T2: lb
A4: =July!A16+7 -> 46237 | B4: =ISOWEEKNUM(A4)-1 -> 31 | C4: =July!J16 -> 16.157143 | D4: =C4 -> 16.157143 | E4: =D4 -> 16.157143 | F4: =E4 -> 16.157143 | G4: =F4 -> 16.157143 | H4: =G4 -> 16.157143 | I4: =H4 -> 16.157143 | J4: =I4 -> 16.157143 | K4: =min(D4:J4) -> 16.157143 | L4: =MAX(D4:J4) -> 16.157143 | M4: =AVERAGE(D4:J4) -> 16.157143 | N4: =L4-K4 -> 0 | O4: =J4-D4 -> 0 | P4: =O4*14 -> 0 | Q4: ='Target-st'!J41 -> 15.375 | R4: =K4 -> 16.157143 | S4: =Q4-R4 -> -0.78214286 | T4: =S4*14 -> -10.95
D5: =D4-C4 -> 0 | E5: =E4-D4 -> 0 | F5: =F4-E4 -> 0 | G5: =G4-F4 -> 0 | H5: =H4-G4 -> 0 | I5: =I4-H4 -> 0 | J5: =J4-I4 -> 0
D6: =D5*14 -> 0 | E6: =E5*14 -> 0 | F6: =F5*14 -> 0 | G6: =G5*14 -> 0 | H6: =H5*14 -> 0 | I6: =I5*14 -> 0 | J6: =J5*14 -> 0
A8: =A4+7 -> 46244 | B8: =B4+1 -> 32 | C8: =J4 -> 16.157143 | D8: =C8 -> 16.157143 | E8: =D8 -> 16.157143 | F8: =E8 -> 16.157143 | G8: =F8 -> 16.157143 | H8: =G8 -> 16.157143 | I8: =H8 -> 16.157143 | J8: =I8 -> 16.157143 | K8: =min(D8:J8) -> 16.157143 | L8: =MAX(D8:J8) -> 16.157143 | M8: =AVERAGE(D8:J8) -> 16.157143 | N8: =L8-K8 -> 0 | O8: =J8-D8 -> 0 | P8: =O8*14 -> 0 | Q8: ='Target-st'!J42 -> 15.25 | R8: =K8 -> 16.157143 | S8: =Q8-R8 -> -0.90714286 | T8: =S8*14 -> -12.7
D9: =D8-C8 -> 0 | E9: =E8-D8 -> 0 | F9: =F8-E8 -> 0 | G9: =G8-F8 -> 0 | H9: =H8-G8 -> 0 | I9: =I8-H8 -> 0 | J9: =J8-I8 -> 0
D10: =D9*14 -> 0 | E10: =E9*14 -> 0 | F10: =F9*14 -> 0 | G10: =G9*14 -> 0 | H10: =H9*14 -> 0 | I10: =I9*14 -> 0 | J10: =J9*14 -> 0
A12: =A8+7 -> 46251 | B12: =B8+1 -> 33 | C12: =J8 -> 16.157143 | D12: =C12 -> 16.157143 | E12: =D12 -> 16.157143 | F12: =E12 -> 16.157143 | G12: =F12 -> 16.157143 | H12: =G12 -> 16.157143 | I12: =H12 -> 16.157143 | J12: =I12 -> 16.157143 | K12: =min(D12:J12) -> 16.157143 | L12: =MAX(D12:J12) -> 16.157143 | M12: =AVERAGE(D12:J12) -> 16.157143 | N12: =L12-K12 -> 0 | O12: =J12-D12 -> 0 | P12: =O12*14 -> 0 | Q12: ='Target-st'!J43 -> 15.125 | R12: =K12 -> 16.157143 | S12: =Q12-R12 -> -1.0321429 | T12: =S12*14 -> -14.45
D13: =D12-C12 -> 0 | E13: =E12-D12 -> 0 | F13: =F12-E12 -> 0 | G13: =G12-F12 -> 0 | H13: =H12-G12 -> 0 | I13: =I12-H12 -> 0 | J13: =J12-I12 -> 0 | Q13: ='Target-st'!G29
D14: =D13*14 -> 0 | E14: =E13*14 -> 0 | F14: =F13*14 -> 0 | G14: =G13*14 -> 0 | H14: =H13*14 -> 0 | I14: =I13*14 -> 0 | J14: =J13*14 -> 0
A16: =A12+7 -> 46258 | B16: =B12+1 -> 34 | C16: =J12 -> 16.157143 | D16: =C16 -> 16.157143 | E16: =D16 -> 16.157143 | F16: =E16 -> 16.157143 | G16: =F16 -> 16.157143 | H16: =G16 -> 16.157143 | I16: =H16 -> 16.157143 | J16: =I16 -> 16.157143 | K16: =min(D16:J16) -> 16.157143 | L16: =MAX(D16:J16) -> 16.157143 | M16: =AVERAGE(D16:J16) -> 16.157143 | N16: =L16-K16 -> 0 | O16: =J16-D16 -> 0 | P16: =O16*14 -> 0 | Q16: ='Target-st'!J44 -> 15 | R16: =K16 -> 16.157143 | S16: =Q16-R16 -> -1.1571429 | T16: =S16*14 -> -16.2
D17: =D16-C16 -> 0 | E17: =E16-D16 -> 0 | F17: =F16-E16 -> 0 | G17: =G16-F16 -> 0 | H17: =H16-G16 -> 0 | I17: =I16-H16 -> 0 | J17: =J16-I16 -> 0
D18: =D17*14 -> 0 | E18: =E17*14 -> 0 | F18: =F17*14 -> 0 | G18: =G17*14 -> 0 | H18: =H17*14 -> 0 | I18: =I17*14 -> 0 | J18: =J17*14 -> 0
A19: =A16+7 -> 46265 | B19: =ISOWEEKNUM(A19)-1 -> 35 | C19: =April!J20 -> 19 | D19: =C19 -> 19 | E19: =D19 -> 19 | F19: =E19 -> 19 | G19: =F19 -> 19 | H19: =G19 -> 19 | I19: =H19 -> 19 | J19: =I19 -> 19 | K19: =min(D19:J19) -> 19 | L19: =MAX(D19:J19) -> 19 | M19: =AVERAGE(D19:J19) -> 19 | N19: =L19-K19 -> 0 | O19: =J19-D19 -> 0 | P19: =O19*14 -> 0 | Q19: ='Target-st'!K50 -> 14.375 | R19: =K19 -> 19 | S19: =Q19-R19 -> -4.625 | T19: =S19*14 -> -64.75
D20: =D19-C19 -> 0 | E20: =E19-D19 -> 0 | F20: =F19-E19 -> 0 | G20: =G19-F19 -> 0 | H20: =H19-G19 -> 0 | I20: =I19-H19 -> 0 | J20: =J19-I19 -> 0
D21: =D20*14 -> 0 | E21: =E20*14 -> 0 | F21: =F20*14 -> 0 | G21: =G20*14 -> 0 | H21: =H20*14 -> 0 | I21: =I20*14 -> 0 | J21: =J20*14 -> 0

Sheet September
A2: =text(A4,"MMMM") -> September | B2: Week no | C2: Per Week | D2: M | E2: T | F2: W | G2: T | H2: F | I2: S | J2: S | K2: Weekly Min (st) | L2: Weekly Max (st) | M2: Average (st) | N2: Weekly Range (st) | O2: Weekly Change (st) | P2: Weekly Change (lb) | Q2: Weekly Target (st) | R2: Weekly Min (st) | S2: Net Achievement (st) | T2: lb
A4: =August!A19+7 -> 46272 | B4: =ISOWEEKNUM(A4)-1 -> 36 | C4: =August!J19 -> 19 | D4: =C4 -> 19 | E4: =D4 -> 19 | F4: =E4 -> 19 | G4: =F4 -> 19 | H4: =G4 -> 19 | I4: =H4 -> 19 | J4: =I4 -> 19 | K4: =min(D4:J4) -> 19 | L4: =MAX(D4:J4) -> 19 | M4: =AVERAGE(D4:J4) -> 19 | N4: =L4-K4 -> 0 | O4: =J4-D4 -> 0 | P4: =O4*14 -> 0 | Q4: ='Target-st'!K47 -> 14.75 | R4: =K4 -> 19 | S4: =Q4-R4 -> -4.25 | T4: =S4*14 -> -59.5
D5: =D4-C4 -> 0 | E5: =E4-D4 -> 0 | F5: =F4-E4 -> 0 | G5: =G4-F4 -> 0 | H5: =H4-G4 -> 0 | I5: =I4-H4 -> 0 | J5: =J4-I4 -> 0
D6: =D5*14 -> 0 | E6: =E5*14 -> 0 | F6: =F5*14 -> 0 | G6: =G5*14 -> 0 | H6: =H5*14 -> 0 | I6: =I5*14 -> 0 | J6: =J5*14 -> 0
A8: =A4+7 -> 46279 | B8: =B4+1 -> 37 | C8: =J4 -> 19 | D8: =C8 -> 19 | E8: =D8 -> 19 | F8: =E8 -> 19 | G8: =F8 -> 19 | H8: =G8 -> 19 | I8: =H8 -> 19 | J8: =I8 -> 19 | K8: =min(D8:J8) -> 19 | L8: =MAX(D8:J8) -> 19 | M8: =AVERAGE(D8:J8) -> 19 | N8: =L8-K8 -> 0 | O8: =J8-D8 -> 0 | P8: =O8*14 -> 0 | Q8: ='Target-st'!K48 -> 14.625 | R8: =K8 -> 19 | S8: =Q8-R8 -> -4.375 | T8: =S8*14 -> -61.25
D9: =D8-C8 -> 0 | E9: =E8-D8 -> 0 | F9: =F8-E8 -> 0 | G9: =G8-F8 -> 0 | H9: =H8-G8 -> 0 | I9: =I8-H8 -> 0 | J9: =J8-I8 -> 0 | Q9: ='Target-st'!G29
D10: =D9*14 -> 0 | E10: =E9*14 -> 0 | F10: =F9*14 -> 0 | G10: =G9*14 -> 0 | H10: =H9*14 -> 0 | I10: =I9*14 -> 0 | J10: =J9*14 -> 0
A12: =A8+7 -> 46286 | B12: =B8+1 -> 38 | C12: =J8 -> 19 | D12: =C12 -> 19 | E12: =D12 -> 19 | F12: =E12 -> 19 | G12: =F12 -> 19 | H12: =G12 -> 19 | I12: =H12 -> 19 | J12: =I12 -> 19 | K12: =min(D12:J12) -> 19 | L12: =MAX(D12:J12) -> 19 | M12: =AVERAGE(D12:J12) -> 19 | N12: =L12-K12 -> 0 | O12: =J12-D12 -> 0 | P12: =O12*14 -> 0 | Q12: ='Target-st'!K49 -> 14.5 | R12: =K12 -> 19 | S12: =Q12-R12 -> -4.5 | T12: =S12*14 -> -63
D13: =D12-C12 -> 0 | E13: =E12-D12 -> 0 | F13: =F12-E12 -> 0 | G13: =G12-F12 -> 0 | H13: =H12-G12 -> 0 | I13: =I12-H12 -> 0 | J13: =J12-I12 -> 0
D14: =D13*14 -> 0 | E14: =E13*14 -> 0 | F14: =F13*14 -> 0 | G14: =G13*14 -> 0 | H14: =H13*14 -> 0 | I14: =I13*14 -> 0 | J14: =J13*14 -> 0
A16: =A12+7 -> 46293 | B16: =B12+1 -> 39 | C16: =J12 -> 19 | D16: =C16 -> 19 | E16: =D16 -> 19 | F16: =E16 -> 19 | G16: =F16 -> 19 | H16: =G16 -> 19 | I16: =H16 -> 19 | J16: =I16 -> 19 | K16: =min(D16:J16) -> 19 | L16: =MAX(D16:J16) -> 19 | M16: =AVERAGE(D16:J16) -> 19 | N16: =L16-K16 -> 0 | O16: =J16-D16 -> 0 | P16: =O16*14 -> 0 | Q16: ='Target-st'!K50 -> 14.375 | R16: =K16 -> 19 | S16: =Q16-R16 -> -4.625 | T16: =S16*14 -> -64.75
D17: =D16-C16 -> 0 | E17: =E16-D16 -> 0 | F17: =F16-E16 -> 0 | G17: =G16-F16 -> 0 | H17: =H16-G16 -> 0 | I17: =I16-H16 -> 0 | J17: =J16-I16 -> 0
D18: =D17*14 -> 0 | E18: =E17*14 -> 0 | F18: =F17*14 -> 0 | G18: =G17*14 -> 0 | H18: =H17*14 -> 0 | I18: =I17*14 -> 0 | J18: =J17*14 -> 0

Sheet October
A2: =text(A4,"MMMM") -> October | B2: Week no | C2: Per Week | D2: M | E2: T | F2: W | G2: T | H2: F | I2: S | J2: S | K2: Weekly Min (st) | L2: Weekly Max (st) | M2: Average (st) | N2: Weekly Range (st) | O2: Weekly Change (st) | P2: Weekly Change (lb) | Q2: Weekly Target (st) | R2: Weekly Min (st) | S2: Net Achievement (st) | T2: lb
A4: =September!A16+7 -> 46300 | B4: =ISOWEEKNUM(A4)-1 -> 40 | C4: =August!J19 -> 19 | D4: =C4 -> 19 | E4: =D4 -> 19 | F4: =E4 -> 19 | G4: =F4 -> 19 | H4: =G4 -> 19 | I4: =H4 -> 19 | J4: =I4 -> 19 | K4: =min(D4:J4) -> 19 | L4: =MAX(D4:J4) -> 19 | M4: =AVERAGE(D4:J4) -> 19 | N4: =L4-K4 -> 0 | O4: =J4-D4 -> 0 | P4: =O4*14 -> 0 | Q4: ='Target-st'!L52 -> 14.25 | R4: =K4 -> 19 | S4: =Q4-R4 -> -4.75 | T4: =S4*14 -> -66.5
D5: =D4-C4 -> 0 | E5: =E4-D4 -> 0 | F5: =F4-E4 -> 0 | G5: =G4-F4 -> 0 | H5: =H4-G4 -> 0 | I5: =I4-H4 -> 0 | J5: =J4-I4 -> 0
D6: =D5*14 -> 0 | E6: =E5*14 -> 0 | F6: =F5*14 -> 0 | G6: =G5*14 -> 0 | H6: =H5*14 -> 0 | I6: =I5*14 -> 0 | J6: =J5*14 -> 0
A8: =A4+7 -> 46307 | B8: =B4+1 -> 41 | C8: =J4 -> 19 | D8: =C8 -> 19 | E8: =D8 -> 19 | F8: =E8 -> 19 | G8: =F8 -> 19 | H8: =G8 -> 19 | I8: =H8 -> 19 | J8: =I8 -> 19 | K8: =min(D8:J8) -> 19 | L8: =MAX(D8:J8) -> 19 | M8: =AVERAGE(D8:J8) -> 19 | N8: =L8-K8 -> 0 | O8: =J8-D8 -> 0 | P8: =O8*14 -> 0 | Q8: ='Target-st'!L53 -> 14.125 | R8: =K8 -> 19 | S8: =Q8-R8 -> -4.875 | T8: =S8*14 -> -68.25
D9: =D8-C8 -> 0 | E9: =E8-D8 -> 0 | F9: =F8-E8 -> 0 | G9: =G8-F8 -> 0 | H9: =H8-G8 -> 0 | I9: =I8-H8 -> 0 | J9: =J8-I8 -> 0 | Q9: ='Target-st'!G29
D10: =D9*14 -> 0 | E10: =E9*14 -> 0 | F10: =F9*14 -> 0 | G10: =G9*14 -> 0 | H10: =H9*14 -> 0 | I10: =I9*14 -> 0 | J10: =J9*14 -> 0
A12: =A8+7 -> 46314 | B12: =B8+1 -> 42 | C12: =J8 -> 19 | D12: =C12 -> 19 | E12: =D12 -> 19 | F12: =E12 -> 19 | G12: =F12 -> 19 | H12: =G12 -> 19 | I12: =H12 -> 19 | J12: =I12 -> 19 | K12: =min(D12:J12) -> 19 | L12: =MAX(D12:J12) -> 19 | M12: =AVERAGE(D12:J12) -> 19 | N12: =L12-K12 -> 0 | O12: =J12-D12 -> 0 | P12: =O12*14 -> 0 | Q12: ='Target-st'!L54 -> 14 | R12: =K12 -> 19 | S12: =Q12-R12 -> -5 | T12: =S12*14 -> -70
D13: =D12-C12 -> 0 | E13: =E12-D12 -> 0 | F13: =F12-E12 -> 0 | G13: =G12-F12 -> 0 | H13: =H12-G12 -> 0 | I13: =I12-H12 -> 0 | J13: =J12-I12 -> 0
D14: =D13*14 -> 0 | E14: =E13*14 -> 0 | F14: =F13*14 -> 0 | G14: =G13*14 -> 0 | H14: =H13*14 -> 0 | I14: =I13*14 -> 0 | J14: =J13*14 -> 0
A16: =A12+7 -> 46321 | B16: =B12+1 -> 43 | C16: =J12 -> 19 | D16: =C16 -> 19 | E16: =D16 -> 19 | F16: =E16 -> 19 | G16: =F16 -> 19 | H16: =G16 -> 19 | I16: =H16 -> 19 | J16: =I16 -> 19 | K16: =min(D16:J16) -> 19 | L16: =MAX(D16:J16) -> 19 | M16: =AVERAGE(D16:J16) -> 19 | N16: =L16-K16 -> 0 | O16: =J16-D16 -> 0 | P16: =O16*14 -> 0 | Q16: ='Target-st'!L55 -> 13.875 | R16: =K16 -> 19 | S16: =Q16-R16 -> -5.125 | T16: =S16*14 -> -71.75
D17: =D16-C16 -> 0 | E17: =E16-D16 -> 0 | F17: =F16-E16 -> 0 | G17: =G16-F16 -> 0 | H17: =H16-G16 -> 0 | I17: =I16-H16 -> 0 | J17: =J16-I16 -> 0
D18: =D17*14 -> 0 | E18: =E17*14 -> 0 | F18: =F17*14 -> 0 | G18: =G17*14 -> 0 | H18: =H17*14 -> 0 | I18: =I17*14 -> 0 | J18: =J17*14 -> 0

Sheet November
A2: =text(A4,"MMMM") -> November | B2: Week no | C2: Per Week | D2: M | E2: T | F2: W | G2: T | H2: F | I2: S | J2: S | K2: Weekly Min (st) | L2: Weekly Max (st) | M2: Average (st) | N2: Weekly Range (st) | O2: Weekly Change (st) | P2: Weekly Change (lb) | Q2: Weekly Target (st) | R2: Weekly Min (st) | S2: Net Achievement (st) | T2: lb
A4: =October!A16+7 -> 46328 | B4: =ISOWEEKNUM(A4)-1 -> 44 | C4: =April!J20 -> 19 | D4: =C4 -> 19 | E4: =D4 -> 19 | F4: =E4 -> 19 | G4: =F4 -> 19 | H4: =G4 -> 19 | I4: =H4 -> 19 | J4: =I4 -> 19 | K4: =min(D4:J4) -> 19 | L4: =MAX(D4:J4) -> 19 | M4: =AVERAGE(D4:J4) -> 19 | N4: =L4-K4 -> 0 | O4: =J4-D4 -> 0 | P4: =O4*14 -> 0 | Q4: ='Target-st'!M57 -> 13.75 | R4: =K4 -> 19 | S4: =Q4-R4 -> -5.25 | T4: =S4*14 -> -73.5
D5: =D4-C4 -> 0 | E5: =E4-D4 -> 0 | F5: =F4-E4 -> 0 | G5: =G4-F4 -> 0 | H5: =H4-G4 -> 0 | I5: =I4-H4 -> 0 | J5: =J4-I4 -> 0
D6: =D5*14 -> 0 | E6: =E5*14 -> 0 | F6: =F5*14 -> 0 | G6: =G5*14 -> 0 | H6: =H5*14 -> 0 | I6: =I5*14 -> 0 | J6: =J5*14 -> 0
A8: =A4+7 -> 46335 | B8: =B4+1 -> 45 | C8: =J4 -> 19 | D8: =C8 -> 19 | E8: =D8 -> 19 | F8: =E8 -> 19 | G8: =F8 -> 19 | H8: =G8 -> 19 | I8: =H8 -> 19 | J8: =I8 -> 19 | K8: =min(D8:J8) -> 19 | L8: =MAX(D8:J8) -> 19 | M8: =AVERAGE(D8:J8) -> 19 | N8: =L8-K8 -> 0 | O8: =J8-D8 -> 0 | P8: =O8*14 -> 0 | Q8: ='Target-st'!M58 -> 13.625 | R8: =K8 -> 19 | S8: =Q8-R8 -> -5.375 | T8: =S8*14 -> -75.25
D9: =D8-C8 -> 0 | E9: =E8-D8 -> 0 | F9: =F8-E8 -> 0 | G9: =G8-F8 -> 0 | H9: =H8-G8 -> 0 | I9: =I8-H8 -> 0 | J9: =J8-I8 -> 0
D10: =D9*14 -> 0 | E10: =E9*14 -> 0 | F10: =F9*14 -> 0 | G10: =G9*14 -> 0 | H10: =H9*14 -> 0 | I10: =I9*14 -> 0 | J10: =J9*14 -> 0
A12: =A8+7 -> 46342 | B12: =B8+1 -> 46 | C12: =J8 -> 19 | D12: =C12 -> 19 | E12: =D12 -> 19 | F12: =E12 -> 19 | G12: =F12 -> 19 | H12: =G12 -> 19 | I12: =H12 -> 19 | J12: =I12 -> 19 | K12: =min(D12:J12) -> 19 | L12: =MAX(D12:J12) -> 19 | M12: =AVERAGE(D12:J12) -> 19 | N12: =L12-K12 -> 0 | O12: =J12-D12 -> 0 | P12: =O12*14 -> 0 | Q12: ='Target-st'!M59 -> 13.5 | R12: =K12 -> 19 | S12: =Q12-R12 -> -5.5 | T12: =S12*14 -> -77
D13: =D12-C12 -> 0 | E13: =E12-D12 -> 0 | F13: =F12-E12 -> 0 | G13: =G12-F12 -> 0 | H13: =H12-G12 -> 0 | I13: =I12-H12 -> 0 | J13: =J12-I12 -> 0 | Q13: ='Target-st'!G29
D14: =D13*14 -> 0 | E14: =E13*14 -> 0 | F14: =F13*14 -> 0 | G14: =G13*14 -> 0 | H14: =H13*14 -> 0 | I14: =I13*14 -> 0 | J14: =J13*14 -> 0
A16: =A12+7 -> 46349 | B16: =B12+1 -> 47 | C16: =J12 -> 19 | D16: =C16 -> 19 | E16: =D16 -> 19 | F16: =E16 -> 19 | G16: =F16 -> 19 | H16: =G16 -> 19 | I16: =H16 -> 19 | J16: =I16 -> 19 | K16: =min(D16:J16) -> 19 | L16: =MAX(D16:J16) -> 19 | M16: =AVERAGE(D16:J16) -> 19 | N16: =L16-K16 -> 0 | O16: =J16-D16 -> 0 | P16: =O16*14 -> 0 | Q16: ='Target-st'!M60 -> 13.375 | R16: =K16 -> 19 | S16: =Q16-R16 -> -5.625 | T16: =S16*14 -> -78.75
D17: =D16-C16 -> 0 | E17: =E16-D16 -> 0 | F17: =F16-E16 -> 0 | G17: =G16-F16 -> 0 | H17: =H16-G16 -> 0 | I17: =I16-H16 -> 0 | J17: =J16-I16 -> 0
D18: =D17*14 -> 0 | E18: =E17*14 -> 0 | F18: =F17*14 -> 0 | G18: =G17*14 -> 0 | H18: =H17*14 -> 0 | I18: =I17*14 -> 0 | J18: =J17*14 -> 0
A20: =A16+7 -> 46356 | B20: =B16+1 -> 48 | C20: =J16 -> 19 | D20: =C20 -> 19 | E20: =D20 -> 19 | F20: =E20 -> 19 | G20: =F20 -> 19 | H20: =G20 -> 19 | I20: =H20 -> 19 | J20: =I20 -> 19 | K20: =min(D20:J20) -> 19 | L20: =MAX(D20:J20) -> 19 | M20: =AVERAGE(D20:J20) -> 19 | N20: =L20-K20 -> 0 | O20: =J20-D20 -> 0 | P20: =O20*14 -> 0 | Q20: ='Target-st'!M61 -> 13.25 | R20: =K20 -> 19 | S20: =Q20-R20 -> -5.75 | T20: =S20*14 -> -80.5
D21: =D20-C20 -> 0 | E21: =E20-D20 -> 0 | F21: =F20-E20 -> 0 | G21: =G20-F20 -> 0 | H21: =H20-G20 -> 0 | I21: =I20-H20 -> 0 | J21: =J20-I20 -> 0
D22: =D21*14 -> 0 | E22: =E21*14 -> 0 | F22: =F21*14 -> 0 | G22: =G21*14 -> 0 | H22: =H21*14 -> 0 | I22: =I21*14 -> 0 | J22: =J21*14 -> 0

Sheet December
A2: =text(A4,"MMMM") -> December | B2: Week no | C2: Per Week | D2: M | E2: T | F2: W | G2: T | H2: F | I2: S | J2: S | K2: Weekly Min (st) | L2: Weekly Max (st) | M2: Average (st) | N2: Weekly Range (st) | O2: Weekly Change (st) | P2: Weekly Change (lb) | Q2: Weekly Target (st) | R2: Weekly Min (st) | S2: Net Achievement (st) | T2: lb
A4: =November!A20+7 -> 46363 | B4: =ISOWEEKNUM(A4)-1 -> 49 | C4: =April!J20 -> 19 | D4: =C4 -> 19 | E4: =D4 -> 19 | F4: =E4 -> 19 | G4: =F4 -> 19 | H4: =G4 -> 19 | I4: =H4 -> 19 | J4: =I4 -> 19 | K4: =min(D4:J4) -> 19 | L4: =MAX(D4:J4) -> 19 | M4: =AVERAGE(D4:J4) -> 19 | N4: =L4-K4 -> 0 | O4: =J4-D4 -> 0 | P4: =O4*14 -> 0 | Q4: ='Target-st'!N63 -> 13.125 | R4: =K4 -> 19 | S4: =Q4-R4 -> -5.875 | T4: =S4*14 -> -82.25
D5: =D4-C4 -> 0 | E5: =E4-D4 -> 0 | F5: =F4-E4 -> 0 | G5: =G4-F4 -> 0 | H5: =H4-G4 -> 0 | I5: =I4-H4 -> 0 | J5: =J4-I4 -> 0
D6: =D5*14 -> 0 | E6: =E5*14 -> 0 | F6: =F5*14 -> 0 | G6: =G5*14 -> 0 | H6: =H5*14 -> 0 | I6: =I5*14 -> 0 | J6: =J5*14 -> 0
A8: =A4+7 -> 46370 | B8: =B4+1 -> 50 | C8: =J4 -> 19 | D8: =C8 -> 19 | E8: =D8 -> 19 | F8: =E8 -> 19 | G8: =F8 -> 19 | H8: =G8 -> 19 | I8: =H8 -> 19 | J8: =I8 -> 19 | K8: =min(D8:J8) -> 19 | L8: =MAX(D8:J8) -> 19 | M8: =AVERAGE(D8:J8) -> 19 | N8: =L8-K8 -> 0 | O8: =J8-D8 -> 0 | P8: =O8*14 -> 0 | Q8: ='Target-st'!N64 -> 13 | R8: =K8 -> 19 | S8: =Q8-R8 -> -6 | T8: =S8*14 -> -84
D9: =D8-C8 -> 0 | E9: =E8-D8 -> 0 | F9: =F8-E8 -> 0 | G9: =G8-F8 -> 0 | H9: =H8-G8 -> 0 | I9: =I8-H8 -> 0 | J9: =J8-I8 -> 0
D10: =D9*14 -> 0 | E10: =E9*14 -> 0 | F10: =F9*14 -> 0 | G10: =G9*14 -> 0 | H10: =H9*14 -> 0 | I10: =I9*14 -> 0 | J10: =J9*14 -> 0
A12: =A8+7 -> 46377 | B12: =B8+1 -> 51 | C12: =J8 -> 19 | D12: =C12 -> 19 | E12: =D12 -> 19 | F12: =E12 -> 19 | G12: =F12 -> 19 | H12: =G12 -> 19 | I12: =H12 -> 19 | J12: =I12 -> 19 | K12: =min(D12:J12) -> 19 | L12: =MAX(D12:J12) -> 19 | M12: =AVERAGE(D12:J12) -> 19 | N12: =L12-K12 -> 0 | O12: =J12-D12 -> 0 | P12: =O12*14 -> 0 | Q12: ='Target-st'!N65 -> 12.875 | R12: =K12 -> 19 | S12: =Q12-R12 -> -6.125 | T12: =S12*14 -> -85.75
D13: =D12-C12 -> 0 | E13: =E12-D12 -> 0 | F13: =F12-E12 -> 0 | G13: =G12-F12 -> 0 | H13: =H12-G12 -> 0 | I13: =I12-H12 -> 0 | J13: =J12-I12 -> 0 | Q13: ='Target-st'!G29
D14: =D13*14 -> 0 | E14: =E13*14 -> 0 | F14: =F13*14 -> 0 | G14: =G13*14 -> 0 | H14: =H13*14 -> 0 | I14: =I13*14 -> 0 | J14: =J13*14 -> 0
A16: =A12+7 -> 46384 | B16: =B12+1 -> 52 | C16: =J12 -> 19 | D16: =C16 -> 19 | E16: =D16 -> 19 | F16: =E16 -> 19 | G16: =F16 -> 19 | H16: =G16 -> 19 | I16: =H16 -> 19 | J16: =I16 -> 19 | K16: =min(D16:J16) -> 19 | L16: =MAX(D16:J16) -> 19 | M16: =AVERAGE(D16:J16) -> 19 | N16: =L16-K16 -> 0 | O16: =J16-D16 -> 0 | P16: =O16*14 -> 0 | Q16: ='Target-st'!N66 -> 12.75 | R16: =K16 -> 19 | S16: =Q16-R16 -> -6.25 | T16: =S16*14 -> -87.5
D17: =D16-C16 -> 0 | E17: =E16-D16 -> 0 | F17: =F16-E16 -> 0 | G17: =G16-F16 -> 0 | H17: =H16-G16 -> 0 | I17: =I16-H16 -> 0 | J17: =J16-I16 -> 0
D18: =D17*14 -> 0 | E18: =E17*14 -> 0 | F18: =F17*14 -> 0 | G18: =G17*14 -> 0 | H18: =H17*14 -> 0 | I18: =I17*14 -> 0 | J18: =J17*14 -> 0
