Workbook

Sheet Project Status
B2: Milestone | C2: Planned Target
B4: Inital MVS Release | C4: 46174
B5: Baseline Implementaiton Plan | C5: 46204
B6: Stable WIMS Platform | C6: September 206

Sheet Key Deliverables - Milestones
C2: PD | D2: Q1 | E2: Q1 | F2: Q1 | G2: Q2 | H2: Q2 | I2: Q2 | J2: Q3 | K2: Q3 | L2: Q3 | M2: Q4 | N2: Q4 | O2: Q4
B3: Deliverables | D3: 46204 | E3: =D3+31 -> 46235 | F3: =E3+31 -> 46266 | G3: =F3+31 -> 46297 | H3: =G3+31 -> 46328 | I3: =H3+31 -> 46359 | J3: =I3+31 -> 46390 | K3: =J3+31 -> 46421 | L3: =K3+31 -> 46452 | ... O3: =N3+31 -> 46545
B5: WIMS SD & I Plan | D5: PF
B7: Work Streams
B9: 1.0 WIMS Book | C9: WBK | O9: Due
B11: 2.0 WIMS Educational Platform | C11: WEP | D11: R1.1 | E11: R1.2 | F11: R.3
B13: 3.0 WIMS Educational Content | C13: WEC | E13: WBS | F13: WBS
B15: 4.0 WIMS Practical Theory | C15: WPT
B17: 5.0 WIMS Community Engagement | C17: WCE
B19: 6.0 WIMS Communications | C19: WCM

Sheet Key Deliverables - Milestones -
D2: PD | E2: Q1 | F2: Q1 | G2: Q1 | H2: Q2 | I2: Q2 | J2: Q2 | K2: Q3 | L2: Q3 | M2: Q3 | N2: Q4 | O2: Q4 | P2: Q4
C3: Deliverables | E3: 46204 | F3: =E3+31 -> 46235 | G3: =F3+31 -> 46266 | H3: =G3+31 -> 46297 | I3: =H3+31 -> 46328 | J3: =I3+31 -> 46359 | K3: =J3+31 -> 46390 | L3: =K3+31 -> 46421 | M3: =L3+31 -> 46452 | ... P3: =O3+31 -> 46545 | Q3: Totals
B4: PM | E4: PM01 | F4: PM02 | G4: PM03 | H4: PM04 | I4: PM05 | J4: PM06 | K4: PM07 | L4: PM08 | M4: PM09 | N4: PM10 | O4: PM11 | P4: PM12
B5: PW | E5: 4 | F5: 5 | G5: 4 | H5: 4 | I5: 5 | J5: 4 | K5: 4 | L5: 4 | M5: 5 | N5: 4 | O5: 5 | P5: 4 | Q5: =SUM(E5:P5) -> 52
B6: PD | E6: =E5*5 -> 20 | F6: =F5*5 -> 25 | G6: =G5*5 -> 20 | H6: =H5*5 -> 20 | I6: =I5*5 -> 25 | J6: =J5*5 -> 20 | K6: =K5*5 -> 20 | L6: =L5*5 -> 20 | ... P6: =P5*5 -> 20 | Q6: =SUM(E6:P6) -> 260
C8: WIMS SD & I Plan | E8: 0
C10: Work Streams
C12: 0.0 WIMS Planning | D12: PLN | E12: 4 | F12: 5 | G12: 4 | H12: 4 | I12: 5 | J12: 4 | K12: 4 | L12: 4 | M12: 5 | N12: 5 | O12: 5 | P12: 4 | Q12: =SUM(E12:P12) -> 53
C14: 1.0 WIMS Book | D14: WBK | F14: 0.75 | G14: 0.75 | H14: =H6*0.2 -> 4 | I14: =I6*0.2 -> 5 | J14: =J6*0.2 -> 4 | K14: =K6*0.2 -> 4 | L14: =L6*0.2 -> 4 | M14: =M6*0.2 -> 5 | N14: =N6*0.2 -> 4 | O14: =O6*0.2 -> 5 | P14: =P6*0.2 -> 4 | Q14: =SUM(E14:P14) -> 40.5
C16: 2.0 WIMS Educational Platform | D16: WEP | E16: =E6*0.6 -> 12 | F16: =F6*0.6+0.75 -> 15.75 | G16: =G6*0.6+0.25 -> 12.25 | H16: 1 | I16: 1 | J16: 1 | K16: 1 | L16: 1 | M16: 1 | N16: 1 | O16: 1 | P16: 1 | Q16: =SUM(E16:P16) -> 49
C18: 3.0 WIMS Educational Content | D18: WEC | E18: 4 | F18: 0.75 | G18: 0.75 | H18: 4 | I18: 5 | J18: 4 | K18: 4 | L18: 4 | M18: 5 | N18: 4 | O18: 5 | P18: 1 | Q18: =SUM(E18:P18) -> 41.5
C20: 4.0 WIMS Practical Theory | D20: WPT | F20: 0.75 | G20: 0.75 | H20: 2 | I20: 2.5 | J20: 2 | K20: 2 | L20: 2 | M20: 2.5 | N20: 2 | O20: 2.5 | P20: 2 | Q20: =SUM(E20:P20) -> 21
C22: 5.0 WIMS Community Engagement | D22: WCE | F22: 0.75 | G22: 0.75 | H22: 2 | I22: 2.5 | J22: 2 | K22: 2 | L22: 2 | M22: 2.5 | N22: 2 | O22: 2.5 | P22: 2 | Q22: =SUM(E22:P22) -> 21
C24: 6.0 WIMS Communications | D24: WCM | F24: 0.75 | G24: 0.75 | H24: 2 | I24: 2.5 | J24: 2 | K24: 2 | L24: 2 | M24: 2.5 | N24: 2 | O24: 2.5 | P24: 2 | Q24: =SUM(E24:P24) -> 21
B26: Totals | E26: =sum(E7:E25) -> 20 | F26: =sum(F7:F25) -> 24.5 | G26: =sum(G7:G25) -> 20 | H26: =sum(H7:H25) -> 19 | I26: =sum(I7:I25) -> 23.5 | J26: =sum(J7:J25) -> 19 | K26: =sum(K7:K25) -> 19 | L26: =sum(L7:L25) -> 19 | ... Q26: =sum(Q7:Q25) -> 247 | R26: =sum(E26:P26) -> 247
B27: Unallocated | E27: =E6-E26 -> 0 | F27: =F6-F26 -> 0.5 | G27: =G6-G26 -> 0 | H27: =H6-H26 -> 1 | I27: =I6-I26 -> 1.5 | J27: =J6-J26 -> 1 | K27: =K6-K26 -> 1 | L27: =L6-L26 -> 1 | ... Q27: =Q6-Q26 -> 13 | R27: =sum(E27:P27) -> 13

Sheet Project Key
B2: Key | C2: Project Name | D2: PD | F2: Work Streams | G2: WC | H2: Component Deliverables | I2: CD | K2: Project Action | L2: PN
B5: Project | C5: Project Office | D5: PO | F5: WIMS Book | G5: WBK | K5: Plan | L5: PLN
C6: Project Control | D6: PC | F6: WIMS Education Platform | G6: WEP | K6: Work Break Down Structure | L6: WBS
H7: Human Bioliogy Basics | I7: HBB
C8: Project Year | D8: PY | H8: Human Bioliogy Research | I8: HBR
C9: Project Month | D9: PM | F9: WIMS Education Content | G9: WEC
C10: Project Week | D10: PW | F10: WIMS Practical Theory | G10: WPT
F11: WIMS Community Engagement | G11: WCE
C12: Project Status | D12: PS | F12: WIMS Communication | G12: WCM
B14: Project RAIDD | C14: Project Risk | D14: PR
C15: Project Assumptions | D15: PA
C16: Project Issue | D16: PI
C17: Project Definition | D17: PD
C18: Project Dependency | D18: PY
C20: Project Decisions | D20: PS
C21: Project Park | D21: PP
C23: Project Code | D23: PE

Sheet Project Components
B3: Articles
B4: Reports
B5: Presentations
B6: Website Content
B9: Review
B10: Reference Library
B13: Website Releases
B14: YouTube Content
B15: Social Media
B16: Marketing Materials
B18: Book structure
B19: Draft Chapters
... B21: Publication

Sheet Project Weeks (0)
B2: Project Quarter | C2: Project Month | D2: Project Week # | E2: Start | F2: End
B4: PQ1 | C4: ='Project Calendar'!B4 -> PM01 | D4: PW01 | E4: 46209 | F4: =E4+5-1 -> 46213
D5: PW02 | E5: =E4+7 -> 46216 | F5: =F4+7 -> 46220
D6: PW03 | E6: =E5+7 -> 46223 | F6: =E6+5-1 -> 46227
D7: PW04 | E7: =E6+7 -> 46230 | F7: =F6+7 -> 46234
B8: PQ1 | C8: ='Project Calendar'!C4 -> PM02 | D8: PW05 | E8: =E7+7 -> 46237 | F8: =E8+5-1 -> 46241
D9: PW06 | E9: =E8+7 -> 46244 | F9: =F8+7 -> 46248
D10: PW07 | E10: =E9+7 -> 46251 | F10: =E10+5-1 -> 46255
D11: PW08 | E11: =E10+7 -> 46258 | F11: =F10+7 -> 46262
D12: PW09 | E12: =E11+7 -> 46265 | F12: =E12+5-1 -> 46269
B13: PQ1 | C13: ='Project Calendar'!D4 -> PM03 | D13: PW10 | E13: =E12+7 -> 46272 | F13: =F12+7 -> 46276
D14: PW11 | E14: =E13+7 -> 46279 | F14: =E14+5-1 -> 46283
D15: PW12 | E15: =E14+7 -> 46286 | F15: =F14+7 -> 46290
D16: PW13 | E16: =E15+7 -> 46293 | F16: =E16+5-1 -> 46297
B17: PQ2 | C17: ='Project Calendar'!F4 -> PM04 | D17: PW14 | E17: =E16+7 -> 46300 | F17: =F16+7 -> 46304
D18: PW15 | E18: =E17+7 -> 46307 | F18: =E18+5-1 -> 46311
D19: PW16 | E19: =E18+7 -> 46314 | F19: =F18+7 -> 46318
D20: PW17 | E20: =E19+7 -> 46321 | F20: =E20+5-1 -> 46325
B21: PQ2 | C21: ='Project Calendar'!G4 -> PM05 | D21: PW18 | E21: =E20+7 -> 46328 | F21: =F20+7 -> 46332
D22: PW19 | E22: =E21+7 -> 46335 | F22: =E22+5-1 -> 46339
D23: PW20 | E23: =E22+7 -> 46342 | F23: =F22+7 -> 46346
D24: PW21 | E24: =E23+7 -> 46349 | F24: =E24+5-1 -> 46353
D25: PW22 | E25: =E24+7 -> 46356 | F25: =F24+7 -> 46360
B26: PQ3 | C26: ='Project Calendar'!H4 -> PM06 | D26: PW23 | E26: =E25+7 -> 46363 | F26: =E26+5-1 -> 46367
D27: PW24 | E27: =E26+7 -> 46370 | F27: =F26+7 -> 46374
D28: PW25 | E28: =E27+7 -> 46377 | F28: =E28+5-1 -> 46381
D29: PW26 | E29: =E28+7 -> 46384 | F29: =F28+7 -> 46388
B30: PQ3 | C30: ='Project Calendar'!J4 -> PM07 | D30: PW27 | E30: =E29+7 -> 46391 | F30: =E30+5-1 -> 46395
D31: PW28 | E31: =E30+7 -> 46398 | F31: =F30+7 -> 46402
D32: PW29 | E32: =E31+7 -> 46405 | F32: =E32+5-1 -> 46409
D33: PW30 | E33: =E32+7 -> 46412 | F33: =F32+7 -> 46416
B34: PQ3 | C34: ='Project Calendar'!K4 -> PM08 | D34: PW31 | E34: =E33+7 -> 46419 | F34: =E34+5-1 -> 46423
D35: PW32 | E35: =E34+7 -> 46426 | F35: =F34+7 -> 46430
D36: PW33 | E36: =E35+7 -> 46433 | F36: =E36+5-1 -> 46437
D37: PW34 | E37: =E36+7 -> 46440 | F37: =E37+5-1 -> 46444
B38: PQ3 | C38: ='Project Calendar'!L4 -> PM09 | D38: PW35 | E38: =E37+7 -> 46447 | F38: =F37+7 -> 46451
D39: PW36 | E39: =E38+7 -> 46454 | F39: =E39+5-1 -> 46458
D40: PW37 | E40: =E39+7 -> 46461 | F40: =F39+7 -> 46465
D41: PW38 | E41: =E40+7 -> 46468 | F41: =E41+5-1 -> 46472
D42: PW39 | E42: =E41+7 -> 46475 | F42: =F41+7 -> 46479
...

Sheet Project Weeks(R)
B2: ='Project Weeks (1)'!C2 -> Calandar Month | C2: ='Project Weeks (1)'!B2 -> Project Quarter | D2: ='Project Weeks (1)'!D2 -> Project Month | E2: Project Week | F2: Start | G2: End | I2: Calandar Month | J2: Project Quarter | K2: Project Month | L2: Project Week | M2: Start | N2: End
B4: =TEXT(F4,"MMMM") -> July | C4: ='Project Weeks (0)'!B4 -> PQ1 | D4: ='Project Weeks (0)'!C4 -> PM01 | E4: ='Project Weeks (0)'!D4 -> PW01 | F4: ='Project Weeks (0)'!E4 -> 46209 | G4: ='Project Weeks (0)'!F4 -> 46213 | I4: =TEXT(M4,"MMMM") -> January | J4: ='Project Weeks (0)'!B30 -> PQ3 | K4: ='Project Weeks (0)'!C30 -> PM07 | L4: ='Project Weeks (0)'!D30 -> PW27 | M4: ='Project Weeks (0)'!E30 -> 46391 | N4: ='Project Weeks (0)'!F30 -> 46395
E5: ='Project Weeks (0)'!D5 -> PW02 | F5: =F4+7 -> 46216 | G5: =G4+7 -> 46220 | J5: ='Project Weeks (0)'!B31 | L5: ='Project Weeks (0)'!D31 -> PW28 | M5: ='Project Weeks (0)'!E31 -> 46398 | N5: ='Project Weeks (0)'!F31 -> 46402
E6: ='Project Weeks (0)'!D6 -> PW03 | F6: =F5+7 -> 46223 | G6: =G5+7 -> 46227 | J6: ='Project Weeks (0)'!B32 | L6: ='Project Weeks (0)'!D32 -> PW29 | M6: ='Project Weeks (0)'!E32 -> 46405 | N6: ='Project Weeks (0)'!F32 -> 46409
E7: ='Project Weeks (0)'!D7 -> PW04 | F7: =F6+7 -> 46230 | G7: =G6+7 -> 46234 | J7: ='Project Weeks (0)'!B33 | L7: ='Project Weeks (0)'!D33 -> PW30 | M7: ='Project Weeks (0)'!E33 -> 46412 | N7: ='Project Weeks (0)'!F33 -> 46416
B9: =TEXT(F9,"MMMM") -> August | C9: ='Project Weeks (0)'!B8 -> PQ1 | D9: ='Project Weeks (0)'!C8 -> PM02 | E9: ='Project Weeks (0)'!D8 -> PW05 | F9: ='Project Weeks (0)'!E8 -> 46237 | G9: ='Project Weeks (0)'!F8 -> 46241 | I9: =TEXT(M9,"MMMM") -> February | J9: ='Project Weeks (0)'!B34 -> PQ3 | K9: ='Project Weeks (0)'!C34 -> PM08 | L9: ='Project Weeks (0)'!D34 -> PW31 | M9: ='Project Weeks (0)'!E34 -> 46419 | N9: ='Project Weeks (0)'!F34 -> 46423
E10: ='Project Weeks (0)'!D9 -> PW06 | F10: =F9+7 -> 46244 | G10: =G9+7 -> 46248 | L10: ='Project Weeks (0)'!D35 -> PW32 | M10: ='Project Weeks (0)'!E35 -> 46426 | N10: ='Project Weeks (0)'!F35 -> 46430
E11: ='Project Weeks (0)'!D10 -> PW07 | F11: =F10+7 -> 46251 | G11: =G10+7 -> 46255 | L11: ='Project Weeks (0)'!D36 -> PW33 | M11: ='Project Weeks (0)'!E36 -> 46433 | N11: ='Project Weeks (0)'!F36 -> 46437
E12: ='Project Weeks (0)'!D11 -> PW08 | F12: =F11+7 -> 46258 | G12: =G11+7 -> 46262 | L12: ='Project Weeks (0)'!D37 -> PW34 | M12: ='Project Weeks (0)'!E37 -> 46440 | N12: ='Project Weeks (0)'!F37 -> 46444
E13: ='Project Weeks (0)'!D12 -> PW09 | F13: =F12+7 -> 46265 | G13: =G12+7 -> 46269
B15: =TEXT(F15,"MMMM") -> September | C15: ='Project Weeks (0)'!B13 -> PQ1 | D15: ='Project Weeks (0)'!C13 -> PM03 | E15: ='Project Weeks (0)'!D13 -> PW10 | F15: ='Project Weeks (0)'!E13 -> 46272 | G15: ='Project Weeks (0)'!F13 -> 46276 | I15: =TEXT(M15,"MMMM") -> March | J15: ='Project Weeks (0)'!B38 -> PQ3 | K15: ='Project Weeks (0)'!C38 -> PM09 | L15: ='Project Weeks (0)'!D38 -> PW35 | M15: ='Project Weeks (0)'!E38 -> 46447 | N15: ='Project Weeks (0)'!F38 -> 46451
C16: ='Project Weeks (0)'!B14 | E16: ='Project Weeks (0)'!D14 -> PW11 | F16: =F15+7 -> 46279 | G16: =G15+7 -> 46283 | L16: ='Project Weeks (0)'!D39 -> PW36 | M16: ='Project Weeks (0)'!E39 -> 46454 | N16: ='Project Weeks (0)'!F39 -> 46458
C17: ='Project Weeks (0)'!B15 | E17: ='Project Weeks (0)'!D15 -> PW12 | F17: =F16+7 -> 46286 | G17: =G16+7 -> 46290 | L17: ='Project Weeks (0)'!D40 -> PW37 | M17: ='Project Weeks (0)'!E40 -> 46461 | N17: ='Project Weeks (0)'!F40 -> 46465
C18: ='Project Weeks (0)'!B16 | E18: ='Project Weeks (0)'!D16 -> PW13 | F18: =F17+7 -> 46293 | G18: =G17+7 -> 46297 | L18: ='Project Weeks (0)'!D41 -> PW38 | M18: ='Project Weeks (0)'!E41 -> 46468 | N18: ='Project Weeks (0)'!F41 -> 46472
L19: ='Project Weeks (0)'!D42 -> PW39 | M19: ='Project Weeks (0)'!E42 -> 46475 | N19: ='Project Weeks (0)'!F42 -> 46479
C20: ='Project Weeks (0)'!B18
B21: =TEXT(F21,"MMMM") -> October | C21: ='Project Weeks (0)'!B17 -> PQ2 | D21: ='Project Weeks (0)'!C17 -> PM04 | E21: ='Project Weeks (0)'!D17 -> PW14 | F21: =F18+7 -> 46300 | G21: =G18+7 -> 46304 | I21: =TEXT(M21,"MMMM") -> April | J21: ='Project Weeks (0)'!B43 -> PQ4 | K21: ='Project Weeks (0)'!C43 -> PM10 | L21: ='Project Weeks (0)'!D43 -> PW40 | M21: ='Project Weeks (0)'!E43 -> 46482 | N21: ='Project Weeks (0)'!F43 -> 46486
C22: ='Project Weeks (0)'!B18 | D22: ='Project Weeks (0)'!C18 | E22: ='Project Weeks (0)'!D18 -> PW15 | F22: =F21+7 -> 46307 | G22: =G21+7 -> 46311 | L22: ='Project Weeks (0)'!D44 -> PW41 | M22: ='Project Weeks (0)'!E44 -> 46489 | N22: ='Project Weeks (0)'!F44 -> 46493
C23: ='Project Weeks (0)'!B19 | D23: ='Project Weeks (0)'!C19 | E23: ='Project Weeks (0)'!D19 -> PW16 | F23: =F22+7 -> 46314 | G23: =G22+7 -> 46318 | L23: ='Project Weeks (0)'!D45 -> PW42 | M23: ='Project Weeks (0)'!E45 -> 46496 | N23: ='Project Weeks (0)'!F45 -> 46500
C24: ='Project Weeks (0)'!B20 | D24: ='Project Weeks (0)'!C20 | E24: ='Project Weeks (0)'!D20 -> PW17 | F24: =F23+7 -> 46321 | G24: =G23+7 -> 46325 | L24: ='Project Weeks (0)'!D46 -> PW43 | M24: ='Project Weeks (0)'!E46 -> 46503 | N24: ='Project Weeks (0)'!F46 -> 46507
D25: ='Project Weeks (0)'!C22
B26: =TEXT(F26,"MMMM") -> November | C26: ='Project Weeks (0)'!B21 -> PQ2 | D26: ='Project Weeks (0)'!C21 -> PM05 | E26: ='Project Weeks (0)'!D21 -> PW18 | F26: =F24+7 -> 46328 | G26: =G24+7 -> 46332 | I26: =TEXT(M26,"MMMM") -> May | J26: ='Project Weeks (0)'!B47 -> PQ4 | K26: ='Project Weeks (0)'!C47 -> PM11 | L26: ='Project Weeks (0)'!D47 -> PW44 | M26: ='Project Weeks (0)'!E47 -> 46510 | N26: ='Project Weeks (0)'!F47 -> 46514
C27: ='Project Weeks (0)'!B22 | D27: ='Project Weeks (0)'!C22 | E27: ='Project Weeks (0)'!D22 -> PW19 | F27: ='Project Weeks (0)'!E22 -> 46335 | G27: ='Project Weeks (0)'!F22 -> 46339 | L27: ='Project Weeks (0)'!D48 -> PW45 | M27: ='Project Weeks (0)'!E48 -> 46517 | N27: ='Project Weeks (0)'!F48 -> 46521
C28: ='Project Weeks (0)'!B23 | D28: ='Project Weeks (0)'!C23 | E28: ='Project Weeks (0)'!D23 -> PW20 | F28: ='Project Weeks (0)'!E23 -> 46342 | G28: ='Project Weeks (0)'!F23 -> 46346 | L28: ='Project Weeks (0)'!D49 -> PW46 | M28: ='Project Weeks (0)'!E49 -> 46524 | N28: ='Project Weeks (0)'!F49 -> 46528
C29: ='Project Weeks (0)'!B24 | D29: ='Project Weeks (0)'!C24 | E29: ='Project Weeks (0)'!D24 -> PW21 | F29: ='Project Weeks (0)'!E24 -> 46349 | G29: ='Project Weeks (0)'!F24 -> 46353 | L29: ='Project Weeks (0)'!D50 -> PW47 | M29: ='Project Weeks (0)'!E50 -> 46531 | N29: ='Project Weeks (0)'!F50 -> 46535
C30: ='Project Weeks (0)'!B25 | D30: ='Project Weeks (0)'!C25 | E30: ='Project Weeks (0)'!D25 -> PW22 | F30: ='Project Weeks (0)'!E25 -> 46356 | G30: ='Project Weeks (0)'!F25 -> 46360 | L30: ='Project Weeks (0)'!D51 -> PW48 | M30: ='Project Weeks (0)'!E51 -> 46538 | N30: ='Project Weeks (0)'!F51 -> 46542
B32: =TEXT(F32,"MMMM") -> December | C32: ='Project Weeks (0)'!B26 -> PQ3 | D32: ='Project Weeks (0)'!C26 -> PM06 | E32: ='Project Weeks (0)'!D26 -> PW23 | F32: ='Project Weeks (0)'!E26 -> 46363 | G32: ='Project Weeks (0)'!F26 -> 46367 | I32: =TEXT(M32,"MMMM") -> June | J32: ='Project Weeks (0)'!B52 -> PQ4 | K32: ='Project Weeks (0)'!C52 -> PM12 | L32: ='Project Weeks (0)'!D52 -> PW49 | M32: ='Project Weeks (0)'!E52 -> 46545 | N32: ='Project Weeks (0)'!F52 -> 46549
E33: ='Project Weeks (0)'!D27 -> PW24 | F33: ='Project Weeks (0)'!E27 -> 46370 | G33: ='Project Weeks (0)'!F27 -> 46374 | L33: ='Project Weeks (0)'!D53 -> PW50 | M33: ='Project Weeks (0)'!E53 -> 46552 | N33: ='Project Weeks (0)'!F53 -> 46556
E34: ='Project Weeks (0)'!D28 -> PW25 | F34: ='Project Weeks (0)'!E28 -> 46377 | G34: ='Project Weeks (0)'!F28 -> 46381 | L34: ='Project Weeks (0)'!D54 -> PW51 | M34: ='Project Weeks (0)'!E54 -> 46559 | N34: ='Project Weeks (0)'!F54 -> 46563
E35: ='Project Weeks (0)'!D29 -> PW26 | F35: ='Project Weeks (0)'!E29 -> 46384 | G35: ='Project Weeks (0)'!F29 -> 46388 | L35: ='Project Weeks (0)'!D55 -> PW52 | M35: ='Project Weeks (0)'!E55 -> 46566 | N35: ='Project Weeks (0)'!F55 -> 46570

Sheet Project Calendar
C3: Q1 | G3: Q2 | K3: Q3 | O3: Q4
B4: PM01 | C4: PM02 | D4: PM03 | F4: PM04 | G4: PM05 | H4: PM06 | J4: PM07 | K4: PM08 | L4: PM09 | N4: PM10 | O4: PM11 | P4: PM12 | Q4: Project Weeks
B6: PW01 | C6: PW05 | D6: PW10 | F6: PW14 | G6: PW18 | H6: PW23 | J6: PW27 | K6: PW31 | L6: PW35 | N6: PW40 | O6: PW44 | P6: PW49
B7: PW02 | C7: PW06 | D7: PW11 | F7: PW15 | G7: PW19 | H7: PW24 | J7: PW28 | K7: PW32 | L7: PW36 | N7: PW41 | O7: PW45 | P7: PW50
B8: PW03 | C8: PW07 | D8: PW12 | F8: PW16 | G8: PW20 | H8: PW25 | J8: PW29 | K8: PW33 | L8: PW37 | N8: PW42 | O8: PW46 | P8: PW51
B9: PW04 | C9: PW08 | D9: PW13 | F9: PW17 | G9: PW21 | H9: PW26 | J9: PW30 | K9: PW34 | L9: PW38 | N9: PW43 | O9: PW47 | P9: PW52
C10: PW09 | G10: PW22 | L10: PW39 | O10: PW48
B12: =COUNTA(B6:B10) -> 4 | C12: =COUNTA(C6:C10) -> 5 | D12: =COUNTA(D6:D10) -> 4 | F12: =COUNTA(F6:F10) -> 4 | G12: =COUNTA(G6:G10) -> 5 | H12: =COUNTA(H6:H10) -> 4 | J12: =COUNTA(J6:J10) -> 4 | K12: =COUNTA(K6:K10) -> 4 | L12: =COUNTA(L6:L10) -> 5 | N12: =COUNTA(N6:N10) -> 4 | O12: =COUNTA(O6:O10) -> 5 | P12: =COUNTA(P6:P10) -> 4 | Q12: =sum(B12:P12) -> 52
B13: =A12+B12 -> 4 | C13: =B13+C12 -> 9 | D13: =C13+D12 -> 13 | F13: =D13+F12 -> 17 | G13: =F13+G12 -> 22 | H13: =G13+H12 -> 26 | J13: =H13+J12 -> 30 | K13: =J13+K12 -> 34 | L13: =K13+L12 -> 39 | N13: =L13+N12 -> 43 | O13: =N13+O12 -> 48 | P13: =O13+P12 -> 52 | Q13: =P13-Q12 -> 0 | R13: Cross Check

Sheet Project Weeks (1)
B2: Project Quarter | C2: Calandar Month | D2: Project Month | L2: Project Quarter | M2: Calandar Month | N2: Project Month
B4: PQ1 | C4: =TEXT(F5, "MMMM") -> July | D4: PM01 | E4: Project Week | F4: {=transpose('Project Weeks (0)'!D4:F7)} -> PW01 | G4: PW02 | H4: PW03 | I4: PW04 | L4: PQ3 | M4: =TEXT(P5, "MMMM") -> January | N4: PM07 | O4: Week | P4: {=transpose('Project Weeks (0)'!D30:F33)} -> PW27 | Q4: PW28 | R4: PW29 | S4: PW30
E5: Start | F5: 46209 | G5: 46216 | H5: 46223 | I5: 46230 | O5: Start | P5: 46391 | Q5: 46398 | R5: 46405 | S5: 46412
E6: End | F6: 46213 | G6: 46220 | H6: 46227 | I6: 46234 | O6: End | P6: 46395 | Q6: 46402 | R6: 46409 | S6: 46416
C8: =TEXT(F9, "MMMM") -> August | D8: PM02 | E8: Week | F8: {=transpose('Project Weeks (0)'!D8:F12)} -> PW05 | G8: PW06 | H8: PW07 | I8: PW08 | J8: PW09 | M8: =TEXT(P9, "MMMM") -> February | N8: PM08 | O8: Week | P8: {=transpose('Project Weeks (0)'!D34:F37)} -> PW31 | Q8: PW32 | R8: PW33 | S8: PW34
E9: Start | F9: 46237 | G9: 46244 | H9: 46251 | I9: 46258 | J9: 46265 | O9: Start | P9: 46419 | Q9: 46426 | R9: 46433 | S9: 46440
E10: End | F10: 46241 | G10: 46248 | H10: 46255 | I10: 46262 | J10: 46269 | O10: End | P10: 46423 | Q10: 46430 | R10: 46437 | S10: 46444
C12: =TEXT(F13, "MMMM") -> September | D12: PM03 | E12: Week | F12: {=transpose('Project Weeks (0)'!D13:F16)} -> PW10 | G12: PW11 | H12: PW12 | I12: PW13 | M12: =TEXT(P13, "MMMM") -> March | N12: PM09 | O12: Week | P12: {=transpose('Project Weeks (0)'!D38:F42)} -> PW35 | Q12: PW36 | R12: PW37 | S12: PW38 | T12: PW39
E13: Start | F13: 46272 | G13: 46279 | H13: 46286 | I13: 46293 | O13: Start | P13: 46447 | Q13: 46454 | R13: 46461 | S13: 46468 | T13: 46475
E14: End | F14: 46276 | G14: 46283 | H14: 46290 | I14: 46297 | O14: End | P14: 46451 | Q14: 46458 | R14: 46465 | S14: 46472 | T14: 46479
B16: PQ2 | C16: =TEXT(F17, "MMMM") -> October | D16: PM04 | E16: Week | F16: {=transpose('Project Weeks (0)'!D17:F20)} -> PW14 | G16: PW15 | H16: PW16 | I16: PW17 | L16: PQ4 | M16: =TEXT(P17, "MMMM") -> April | N16: PM10 | O16: Week | P16: {=transpose('Project Weeks (0)'!D43:F46)} -> PW40 | Q16: PW41 | R16: PW42 | S16: PW43
E17: Start | F17: 46300 | G17: 46307 | H17: 46314 | I17: 46321 | O17: Start | P17: 46482 | Q17: 46489 | R17: 46496 | S17: 46503
E18: End | F18: 46304 | G18: 46311 | H18: 46318 | I18: 46325 | O18: End | P18: 46486 | Q18: 46493 | R18: 46500 | S18: 46507
C20: =TEXT(F21, "MMMM") -> November | D20: PM05 | E20: Week | F20: {=transpose('Project Weeks (0)'!D21:F25)} -> PW18 | G20: PW19 | H20: PW20 | I20: PW21 | J20: PW22 | M20: =TEXT(P21, "MMMM") -> May | N20: PM10 | O20: Week | P20: {=transpose('Project Weeks (0)'!D47:F51)} -> PW44 | Q20: PW45 | R20: PW46 | S20: PW47 | T20: PW48
E21: Start | F21: 46328 | G21: 46335 | H21: 46342 | I21: 46349 | J21: 46356 | O21: Start | P21: 46510 | Q21: 46517 | R21: 46524 | S21: 46531 | T21: 46538
E22: End | F22: 46332 | G22: 46339 | H22: 46346 | I22: 46353 | J22: 46360 | O22: End | P22: 46514 | Q22: 46521 | R22: 46528 | S22: 46535 | T22: 46542
C24: =TEXT(F25, "MMMM") -> December | D24: PM06 | E24: Week | F24: {=transpose('Project Weeks (0)'!D26:F29)} -> PW23 | G24: PW24 | H24: PW25 | I24: PW26 | M24: =TEXT(P25, "MMMM") -> June | N24: PM10 | O24: Week | P24: {=transpose('Project Weeks (0)'!D52:F55)} -> PW49 | Q24: PW50 | R24: PW51 | S24: PW52
E25: Start | F25: 46363 | G25: 46370 | H25: 46377 | I25: 46384 | O25: Start | P25: 46545 | Q25: 46552 | R25: 46559 | S25: 46566
E26: End | F26: 46367 | G26: 46374 | H26: 46381 | I26: 46388 | O26: End | P26: 46549 | Q26: 46556 | R26: 46563 | S26: 46570
